WARNING:django.request:Not Found: /
<<<<<<< HEAD
DEBUG:urllib3.connectionpool:Starting new HTTPS connection (1): api.openweathermap.org:443
DEBUG:urllib3.connectionpool:https://api.openweathermap.org:443 "GET /data/2.5/weather?q=Krasnoyarsk&appid=da8eff3043fc441cca70712be72d110b&units=metric HTTP/1.1" 200 523
INFO:django.utils.autoreload:C:\Users\Иван\PycharmProjects\WeatherProject\Wardrobe-Weather-Project\WeatherProject\WeatherProject\settings.py changed, reloading.
WARNING:django.request:Not Found: /
DEBUG:urllib3.connectionpool:Starting new HTTPS connection (1): api.openweathermap.org:443
DEBUG:urllib3.connectionpool:https://api.openweathermap.org:443 "GET /data/2.5/weather?q=Krasnoyarsk&appid=da8eff3043fc441cca70712be72d110b&units=metric HTTP/1.1" 200 523
DEBUG:urllib3.connectionpool:Starting new HTTPS connection (1): api.openweathermap.org:443
DEBUG:urllib3.connectionpool:https://api.openweathermap.org:443 "GET /data/2.5/weather?q=Krasnoyarsk&appid=da8eff3043fc441cca70712be72d110b&units=metric HTTP/1.1" 200 523
DEBUG:urllib3.connectionpool:Starting new HTTPS connection (1): api.openweathermap.org:443
DEBUG:urllib3.connectionpool:https://api.openweathermap.org:443 "GET /data/2.5/weather?q=Krasnoyarsk&appid=da8eff3043fc441cca70712be72d110b&units=metric HTTP/1.1" 200 523
DEBUG:urllib3.connectionpool:Starting new HTTPS connection (1): api.openweathermap.org:443
DEBUG:urllib3.connectionpool:https://api.openweathermap.org:443 "GET /data/2.5/weather?q=Krasnoyarsk&appid=da8eff3043fc441cca70712be72d110b&units=metric HTTP/1.1" 200 523
WARNING:django.request:Not Found: /static/admin/css/base.css
WARNING:django.request:Not Found: /static/admin/css/dark_mode.css
WARNING:django.request:Not Found: /static/admin/css/responsive.css
WARNING:django.request:Not Found: /accounts/login/
WARNING:django.request:Not Found: /static/admin/css/base.css
WARNING:django.request:Not Found: /static/admin/css/dark_mode.css
WARNING:django.request:Not Found: /static/admin/css/nav_sidebar.css
WARNING:django.request:Not Found: /static/admin/css/login.css
WARNING:django.request:Not Found: /static/admin/css/responsive.css
WARNING:django.request:Not Found: /static/admin/js/nav_sidebar.js
WARNING:django.request:Not Found: /static/admin/css/login.css
WARNING:django.request:Not Found: /static/admin/css/responsive.css
WARNING:django.request:Not Found: /static/admin/css/base.css
WARNING:django.request:Not Found: /static/admin/css/dark_mode.css
WARNING:django.request:Not Found: /static/admin/css/responsive.css
WARNING:django.request:Not Found: /static/admin/css/nav_sidebar.css
WARNING:django.request:Not Found: /static/admin/css/dashboard.css
WARNING:django.request:Not Found: /static/admin/js/nav_sidebar.js
WARNING:django.request:Not Found: /static/admin/css/dashboard.css
WARNING:django.request:Not Found: /static/admin/css/responsive.css
WARNING:django.request:Not Found: /static/admin/css/base.css
WARNING:django.request:Not Found: /static/admin/css/nav_sidebar.css
WARNING:django.request:Not Found: /static/admin/css/dark_mode.css
WARNING:django.request:Not Found: /static/admin/css/responsive.css
WARNING:django.request:Not Found: /static/admin/js/nav_sidebar.js
WARNING:django.request:Not Found: /static/admin/css/responsive.css
DEBUG:urllib3.connectionpool:Starting new HTTPS connection (1): github.com:443
DEBUG:urllib3.connectionpool:https://github.com:443 "POST /login/oauth/access_token HTTP/1.1" 200 None
DEBUG:urllib3.connectionpool:Starting new HTTPS connection (1): api.github.com:443
DEBUG:urllib3.connectionpool:https://api.github.com:443 "GET /user HTTP/1.1" 200 None
DEBUG:urllib3.connectionpool:Starting new HTTPS connection (1): api.github.com:443
DEBUG:urllib3.connectionpool:https://api.github.com:443 "GET /user/emails HTTP/1.1" 404 None
ERROR:django.request:Internal Server Error: /complete/github/
Traceback (most recent call last):
  File "C:\Users\Иван\AppData\Local\Programs\Python\Python38\lib\site-packages\django\db\backends\utils.py", line 89, in _execute
    return self.cursor.execute(sql, params)
  File "C:\Users\Иван\AppData\Local\Programs\Python\Python38\lib\site-packages\django\db\backends\sqlite3\base.py", line 357, in execute
    return Database.Cursor.execute(self, query, params)
sqlite3.OperationalError: unknown function: JSON_VALID()

The above exception was the direct cause of the following exception:

Traceback (most recent call last):
  File "C:\Users\Иван\AppData\Local\Programs\Python\Python38\lib\site-packages\django\core\handlers\exception.py", line 55, in inner
    response = get_response(request)
  File "C:\Users\Иван\AppData\Local\Programs\Python\Python38\lib\site-packages\django\core\handlers\base.py", line 197, in _get_response
    response = wrapped_callback(request, *callback_args, **callback_kwargs)
  File "C:\Users\Иван\AppData\Local\Programs\Python\Python38\lib\site-packages\django\views\decorators\cache.py", line 62, in _wrapped_view_func
    response = view_func(request, *args, **kwargs)
  File "C:\Users\Иван\AppData\Local\Programs\Python\Python38\lib\site-packages\django\views\decorators\csrf.py", line 54, in wrapped_view
    return view_func(*args, **kwargs)
  File "C:\Users\Иван\AppData\Local\Programs\Python\Python38\lib\site-packages\social_django\utils.py", line 46, in wrapper
    return func(request, backend, *args, **kwargs)
  File "C:\Users\Иван\AppData\Local\Programs\Python\Python38\lib\site-packages\social_django\views.py", line 31, in complete
    return do_complete(request.backend, _do_login, user=request.user,
  File "C:\Users\Иван\AppData\Local\Programs\Python\Python38\lib\site-packages\social_core\actions.py", line 45, in do_complete
    user = backend.complete(user=user, *args, **kwargs)
  File "C:\Users\Иван\AppData\Local\Programs\Python\Python38\lib\site-packages\social_core\backends\base.py", line 40, in complete
    return self.auth_complete(*args, **kwargs)
  File "C:\Users\Иван\AppData\Local\Programs\Python\Python38\lib\site-packages\social_core\utils.py", line 247, in wrapper
    return func(*args, **kwargs)
  File "C:\Users\Иван\AppData\Local\Programs\Python\Python38\lib\site-packages\social_core\backends\oauth.py", line 401, in auth_complete
    return self.do_auth(response['access_token'], response=response,
  File "C:\Users\Иван\AppData\Local\Programs\Python\Python38\lib\site-packages\social_core\utils.py", line 247, in wrapper
    return func(*args, **kwargs)
  File "C:\Users\Иван\AppData\Local\Programs\Python\Python38\lib\site-packages\social_core\backends\oauth.py", line 413, in do_auth
    return self.strategy.authenticate(*args, **kwargs)
  File "C:\Users\Иван\AppData\Local\Programs\Python\Python38\lib\site-packages\social_django\strategy.py", line 105, in authenticate
    return authenticate(*args, **kwargs)
  File "C:\Users\Иван\AppData\Local\Programs\Python\Python38\lib\site-packages\django\views\decorators\debug.py", line 42, in sensitive_variables_wrapper
    return func(*func_args, **func_kwargs)
  File "C:\Users\Иван\AppData\Local\Programs\Python\Python38\lib\site-packages\django\contrib\auth\__init__.py", line 77, in authenticate
    user = backend.authenticate(request, **credentials)
  File "C:\Users\Иван\AppData\Local\Programs\Python\Python38\lib\site-packages\social_core\backends\base.py", line 80, in authenticate
    return self.pipeline(pipeline, *args, **kwargs)
  File "C:\Users\Иван\AppData\Local\Programs\Python\Python38\lib\site-packages\social_core\backends\base.py", line 83, in pipeline
    out = self.run_pipeline(pipeline, pipeline_index, *args, **kwargs)
  File "C:\Users\Иван\AppData\Local\Programs\Python\Python38\lib\site-packages\social_core\backends\base.py", line 113, in run_pipeline
    result = func(*args, **out) or {}
  File "C:\Users\Иван\AppData\Local\Programs\Python\Python38\lib\site-packages\social_core\pipeline\social_auth.py", line 93, in load_extra_data
    social.set_extra_data(extra_data)
  File "C:\Users\Иван\AppData\Local\Programs\Python\Python38\lib\site-packages\social_django\storage.py", line 20, in set_extra_data
    self.save()
  File "C:\Users\Иван\AppData\Local\Programs\Python\Python38\lib\site-packages\django\db\models\base.py", line 812, in save
    self.save_base(
  File "C:\Users\Иван\AppData\Local\Programs\Python\Python38\lib\site-packages\django\db\models\base.py", line 863, in save_base
    updated = self._save_table(
  File "C:\Users\Иван\AppData\Local\Programs\Python\Python38\lib\site-packages\django\db\models\base.py", line 976, in _save_table
    updated = self._do_update(
  File "C:\Users\Иван\AppData\Local\Programs\Python\Python38\lib\site-packages\django\db\models\base.py", line 1040, in _do_update
    return filtered._update(values) > 0
  File "C:\Users\Иван\AppData\Local\Programs\Python\Python38\lib\site-packages\django\db\models\query.py", line 1216, in _update
    return query.get_compiler(self.db).execute_sql(CURSOR)
  File "C:\Users\Иван\AppData\Local\Programs\Python\Python38\lib\site-packages\django\db\models\sql\compiler.py", line 1822, in execute_sql
    cursor = super().execute_sql(result_type)
  File "C:\Users\Иван\AppData\Local\Programs\Python\Python38\lib\site-packages\django\db\models\sql\compiler.py", line 1398, in execute_sql
    cursor.execute(sql, params)
  File "C:\Users\Иван\AppData\Local\Programs\Python\Python38\lib\site-packages\django\db\backends\utils.py", line 67, in execute
    return self._execute_with_wrappers(
  File "C:\Users\Иван\AppData\Local\Programs\Python\Python38\lib\site-packages\django\db\backends\utils.py", line 80, in _execute_with_wrappers
    return executor(sql, params, many, context)
  File "C:\Users\Иван\AppData\Local\Programs\Python\Python38\lib\site-packages\django\db\backends\utils.py", line 89, in _execute
    return self.cursor.execute(sql, params)
  File "C:\Users\Иван\AppData\Local\Programs\Python\Python38\lib\site-packages\django\db\utils.py", line 91, in __exit__
    raise dj_exc_value.with_traceback(traceback) from exc_value
  File "C:\Users\Иван\AppData\Local\Programs\Python\Python38\lib\site-packages\django\db\backends\utils.py", line 89, in _execute
    return self.cursor.execute(sql, params)
  File "C:\Users\Иван\AppData\Local\Programs\Python\Python38\lib\site-packages\django\db\backends\sqlite3\base.py", line 357, in execute
    return Database.Cursor.execute(self, query, params)
django.db.utils.OperationalError: unknown function: JSON_VALID()
WARNING:django.request:Not Found: /accounts/login/
INFO:django.utils.autoreload:C:\Users\Иван\PycharmProjects\WeatherProject\Wardrobe-Weather-Project\WeatherProject\WeatherProject\settings.py changed, reloading.
WARNING:django.request:Not Found: /accounts/login/
=======
WARNING:django.request:Not Found: /accounts/login/
WARNING:django.request:Not Found: /accounts/login/
WARNING:django.request:Not Found: /accounts/login/
DEBUG:urllib3.connectionpool:Starting new HTTPS connection (1): api.openweathermap.org:443
DEBUG:urllib3.connectionpool:https://api.openweathermap.org:443 "GET /data/2.5/weather?q=Krasnoyarsk&appid=None&units=metric HTTP/1.1" 401 108
DEBUG:urllib3.connectionpool:Starting new HTTPS connection (1): api.openweathermap.org:443
DEBUG:urllib3.connectionpool:https://api.openweathermap.org:443 "GET /data/2.5/weather?q=Krasnoyarsk&appid=None&units=metric HTTP/1.1" 401 108
DEBUG:urllib3.connectionpool:Starting new HTTPS connection (1): api.openweathermap.org:443
DEBUG:urllib3.connectionpool:Starting new HTTPS connection (1): api.openweathermap.org:443
DEBUG:urllib3.connectionpool:https://api.openweathermap.org:443 "GET /data/2.5/weather?q=Krasnoyarsk&appid=None&units=metric HTTP/1.1" 401 108
DEBUG:urllib3.connectionpool:https://api.openweathermap.org:443 "GET /data/2.5/weather?q=Krasnoyarsk&appid=None&units=metric HTTP/1.1" 401 108
ERROR:django.request:Internal Server Error: /weather/
Traceback (most recent call last):
  File "/Users/ivansizov/Documents/work/WeatherProject/venv/lib/python3.9/site-packages/django/core/handlers/exception.py", line 55, in inner
    response = get_response(request)
  File "/Users/ivansizov/Documents/work/WeatherProject/venv/lib/python3.9/site-packages/django/core/handlers/base.py", line 197, in _get_response
    response = wrapped_callback(request, *callback_args, **callback_kwargs)
  File "/Users/ivansizov/Documents/work/WeatherProject/WeatherProject/src/weather/views.py", line 12, in fetch_weather
    city, response, weather_data = fetch_weather_logic(request, user, need_to_fetch=True)
TypeError: fetch_weather_logic() got an unexpected keyword argument 'need_to_fetch'
>>>>>>> bb9b2e9 (??)
WARNING:django.request:Not Found: /
ERROR:django.request:Internal Server Error: /weather/
Traceback (most recent call last):
  File "/Users/ivansizov/Documents/work/WeatherProject/venv/lib/python3.9/site-packages/django/core/handlers/exception.py", line 55, in inner
    response = get_response(request)
  File "/Users/ivansizov/Documents/work/WeatherProject/venv/lib/python3.9/site-packages/django/core/handlers/base.py", line 197, in _get_response
    response = wrapped_callback(request, *callback_args, **callback_kwargs)
  File "/Users/ivansizov/Documents/work/WeatherProject/WeatherProject/src/weather/views.py", line 12, in fetch_weather
    city, response, weather_data = fetch_weather_logic(request, user)
  File "/Users/ivansizov/Documents/work/WeatherProject/WeatherProject/src/weather/services/fetch_weather_logic.py", line 15, in fetch_weather_logic
    client = Client.objects.get(user=user)
  File "/Users/ivansizov/Documents/work/WeatherProject/venv/lib/python3.9/site-packages/django/db/models/manager.py", line 85, in manager_method
    return getattr(self.get_queryset(), name)(*args, **kwargs)
  File "/Users/ivansizov/Documents/work/WeatherProject/venv/lib/python3.9/site-packages/django/db/models/query.py", line 650, in get
    raise self.model.DoesNotExist(
src.client.models.Client.DoesNotExist: Client matching query does not exist.
DEBUG:urllib3.connectionpool:Starting new HTTPS connection (1): api.openweathermap.org:443
DEBUG:urllib3.connectionpool:https://api.openweathermap.org:443 "GET /data/2.5/weather?q=Krasnoyarsk&appid=da8eff3043fc441cca70712be72d110b&units=metric HTTP/1.1" 200 523
DEBUG:urllib3.connectionpool:Starting new HTTPS connection (1): api.openweathermap.org:443
DEBUG:urllib3.connectionpool:https://api.openweathermap.org:443 "GET /data/2.5/weather?q=Krasnoyarsk&appid=da8eff3043fc441cca70712be72d110b&units=metric HTTP/1.1" 200 523
INFO:django.utils.autoreload:/Users/ivansizov/Documents/work/WeatherProject/WeatherProject/src/wardrobe/services/outfit_generation_logic.py changed, reloading.
DEBUG:urllib3.connectionpool:Starting new HTTPS connection (1): api.openweathermap.org:443
DEBUG:urllib3.connectionpool:https://api.openweathermap.org:443 "GET /data/2.5/weather?q=Krasnoyarsk&appid=da8eff3043fc441cca70712be72d110b&units=metric HTTP/1.1" 200 523
INFO:django.utils.autoreload:/Users/ivansizov/Documents/work/WeatherProject/WeatherProject/src/wardrobe/services/outfit_generation_logic.py changed, reloading.
INFO:django.utils.autoreload:/Users/ivansizov/Documents/work/WeatherProject/WeatherProject/src/wardrobe/services/outfit_generation_logic.py changed, reloading.
INFO:django.utils.autoreload:/Users/ivansizov/Documents/work/WeatherProject/WeatherProject/src/wardrobe/services/outfit_generation_logic.py changed, reloading.
DEBUG:urllib3.connectionpool:Starting new HTTPS connection (1): api.openweathermap.org:443
DEBUG:urllib3.connectionpool:https://api.openweathermap.org:443 "GET /data/2.5/weather?q=Krasnoyarsk&appid=da8eff3043fc441cca70712be72d110b&units=metric HTTP/1.1" 200 523
DEBUG:urllib3.connectionpool:Starting new HTTPS connection (1): api.openweathermap.org:443
DEBUG:urllib3.connectionpool:https://api.openweathermap.org:443 "GET /data/2.5/weather?q=Krasnoyarsk&appid=da8eff3043fc441cca70712be72d110b&units=metric HTTP/1.1" 200 523
INFO:django.utils.autoreload:/Users/ivansizov/Documents/work/WeatherProject/WeatherProject/src/wardrobe/services/outfit_generation_logic.py changed, reloading.
DEBUG:urllib3.connectionpool:Starting new HTTPS connection (1): api.openweathermap.org:443
DEBUG:urllib3.connectionpool:https://api.openweathermap.org:443 "GET /data/2.5/weather?q=Krasnoyarsk&appid=da8eff3043fc441cca70712be72d110b&units=metric HTTP/1.1" 200 523
ERROR:django.request:Internal Server Error: /weather/
Traceback (most recent call last):
  File "/Users/ivansizov/Documents/work/WeatherProject/venv/lib/python3.9/site-packages/django/core/handlers/exception.py", line 55, in inner
    response = get_response(request)
  File "/Users/ivansizov/Documents/work/WeatherProject/venv/lib/python3.9/site-packages/django/core/handlers/base.py", line 197, in _get_response
    response = wrapped_callback(request, *callback_args, **callback_kwargs)
  File "/Users/ivansizov/Documents/work/WeatherProject/WeatherProject/src/weather/views.py", line 20, in fetch_weather
    clothes_list_2 = outfit_logic(user, temperature, style_id)
  File "/Users/ivansizov/Documents/work/WeatherProject/WeatherProject/src/wardrobe/services/outfit_generation_logic.py", line 112, in outfit_logic
    fill_clothes_list(filtered_clothes_by_style, temperature, clothes_list)
  File "/Users/ivansizov/Documents/work/WeatherProject/WeatherProject/src/wardrobe/services/outfit_generation_logic.py", line 67, in fill_clothes_list
    for item in clothes:
  File "/Users/ivansizov/Documents/work/WeatherProject/venv/lib/python3.9/site-packages/django/db/models/query.py", line 394, in __iter__
    self._fetch_all()
  File "/Users/ivansizov/Documents/work/WeatherProject/venv/lib/python3.9/site-packages/django/db/models/query.py", line 1867, in _fetch_all
    self._result_cache = list(self._iterable_class(self))
  File "/Users/ivansizov/Documents/work/WeatherProject/venv/lib/python3.9/site-packages/django/db/models/query.py", line 87, in __iter__
    results = compiler.execute_sql(
  File "/Users/ivansizov/Documents/work/WeatherProject/venv/lib/python3.9/site-packages/django/db/models/sql/compiler.py", line 1385, in execute_sql
    sql, params = self.as_sql()
  File "/Users/ivansizov/Documents/work/WeatherProject/venv/lib/python3.9/site-packages/django/db/models/sql/compiler.py", line 593, in as_sql
    extra_select, order_by, group_by = self.pre_sql_setup()
  File "/Users/ivansizov/Documents/work/WeatherProject/venv/lib/python3.9/site-packages/django/db/models/sql/compiler.py", line 71, in pre_sql_setup
    self.setup_query()
  File "/Users/ivansizov/Documents/work/WeatherProject/venv/lib/python3.9/site-packages/django/db/models/sql/compiler.py", line 62, in setup_query
    self.select, self.klass_info, self.annotation_col_map = self.get_select()
  File "/Users/ivansizov/Documents/work/WeatherProject/venv/lib/python3.9/site-packages/django/db/models/sql/compiler.py", line 278, in get_select
    related_klass_infos = self.get_related_selections(select)
  File "/Users/ivansizov/Documents/work/WeatherProject/venv/lib/python3.9/site-packages/django/db/models/sql/compiler.py", line 1193, in get_related_selections
    raise FieldError(
django.core.exceptions.FieldError: Invalid field name(s) given in select_related: 'season'. Choices are: type_of_clothes, owner
INFO:django.utils.autoreload:/Users/ivansizov/Documents/work/WeatherProject/WeatherProject/src/wardrobe/services/outfit_generation_logic.py changed, reloading.
DEBUG:urllib3.connectionpool:Starting new HTTPS connection (1): api.openweathermap.org:443
DEBUG:urllib3.connectionpool:https://api.openweathermap.org:443 "GET /data/2.5/weather?q=Krasnoyarsk&appid=da8eff3043fc441cca70712be72d110b&units=metric HTTP/1.1" 200 523
INFO:django.utils.autoreload:/Users/ivansizov/Documents/work/WeatherProject/WeatherProject/src/wardrobe/services/outfit_generation_logic.py changed, reloading.
DEBUG:urllib3.connectionpool:Starting new HTTPS connection (1): api.openweathermap.org:443
DEBUG:urllib3.connectionpool:https://api.openweathermap.org:443 "GET /data/2.5/weather?q=Krasnoyarsk&appid=da8eff3043fc441cca70712be72d110b&units=metric HTTP/1.1" 200 523
INFO:django.utils.autoreload:/Users/ivansizov/Documents/work/WeatherProject/WeatherProject/src/wardrobe/services/outfit_generation_logic.py changed, reloading.
DEBUG:urllib3.connectionpool:Starting new HTTPS connection (1): api.openweathermap.org:443
DEBUG:urllib3.connectionpool:https://api.openweathermap.org:443 "GET /data/2.5/weather?q=Krasnoyarsk&appid=da8eff3043fc441cca70712be72d110b&units=metric HTTP/1.1" 200 523
INFO:django.utils.autoreload:/Users/ivansizov/Documents/work/WeatherProject/WeatherProject/src/wardrobe/services/outfit_generation_logic.py changed, reloading.
DEBUG:urllib3.connectionpool:Starting new HTTPS connection (1): api.openweathermap.org:443
DEBUG:urllib3.connectionpool:https://api.openweathermap.org:443 "GET /data/2.5/weather?q=Krasnoyarsk&appid=da8eff3043fc441cca70712be72d110b&units=metric HTTP/1.1" 200 523
INFO:django.utils.autoreload:/Users/ivansizov/Documents/work/WeatherProject/WeatherProject/src/wardrobe/services/outfit_generation_logic.py changed, reloading.
DEBUG:urllib3.connectionpool:Starting new HTTPS connection (1): api.openweathermap.org:443
DEBUG:urllib3.connectionpool:https://api.openweathermap.org:443 "GET /data/2.5/weather?q=Krasnoyarsk&appid=da8eff3043fc441cca70712be72d110b&units=metric HTTP/1.1" 200 523
INFO:django.utils.autoreload:/Users/ivansizov/Documents/work/WeatherProject/WeatherProject/src/wardrobe/services/outfit_generation_logic.py changed, reloading.
DEBUG:urllib3.connectionpool:Starting new HTTPS connection (1): api.openweathermap.org:443
DEBUG:urllib3.connectionpool:https://api.openweathermap.org:443 "GET /data/2.5/weather?q=Krasnoyarsk&appid=da8eff3043fc441cca70712be72d110b&units=metric HTTP/1.1" 200 523
DEBUG:urllib3.connectionpool:Starting new HTTPS connection (1): api.openweathermap.org:443
DEBUG:urllib3.connectionpool:https://api.openweathermap.org:443 "GET /data/2.5/weather?q=Krasnoyarsk&appid=da8eff3043fc441cca70712be72d110b&units=metric HTTP/1.1" 200 523
DEBUG:urllib3.connectionpool:Starting new HTTPS connection (1): api.openweathermap.org:443
DEBUG:urllib3.connectionpool:https://api.openweathermap.org:443 "GET /data/2.5/weather?q=Krasnoyarsk&appid=da8eff3043fc441cca70712be72d110b&units=metric HTTP/1.1" 200 523
DEBUG:urllib3.connectionpool:Starting new HTTPS connection (1): api.openweathermap.org:443
DEBUG:urllib3.connectionpool:https://api.openweathermap.org:443 "GET /data/2.5/weather?q=Krasnoyarsk&appid=da8eff3043fc441cca70712be72d110b&units=metric HTTP/1.1" 200 523
DEBUG:urllib3.connectionpool:Starting new HTTPS connection (1): api.openweathermap.org:443
DEBUG:urllib3.connectionpool:https://api.openweathermap.org:443 "GET /data/2.5/weather?q=Krasnoyarsk&appid=da8eff3043fc441cca70712be72d110b&units=metric HTTP/1.1" 200 523
DEBUG:urllib3.connectionpool:Starting new HTTPS connection (1): api.openweathermap.org:443
DEBUG:urllib3.connectionpool:https://api.openweathermap.org:443 "GET /data/2.5/weather?q=Krasnoyarsk&appid=da8eff3043fc441cca70712be72d110b&units=metric HTTP/1.1" 200 523
DEBUG:urllib3.connectionpool:Starting new HTTPS connection (1): api.openweathermap.org:443
DEBUG:urllib3.connectionpool:https://api.openweathermap.org:443 "GET /data/2.5/weather?q=Krasnoyarsk&appid=da8eff3043fc441cca70712be72d110b&units=metric HTTP/1.1" 200 523
INFO:django.utils.autoreload:/Users/ivansizov/Documents/work/WeatherProject/WeatherProject/src/wardrobe/services/outfit_generation_logic.py changed, reloading.
DEBUG:urllib3.connectionpool:Starting new HTTPS connection (1): api.openweathermap.org:443
DEBUG:urllib3.connectionpool:https://api.openweathermap.org:443 "GET /data/2.5/weather?q=Krasnoyarsk&appid=da8eff3043fc441cca70712be72d110b&units=metric HTTP/1.1" 200 523
DEBUG:urllib3.connectionpool:Starting new HTTPS connection (1): api.openweathermap.org:443
DEBUG:urllib3.connectionpool:https://api.openweathermap.org:443 "GET /data/2.5/weather?q=Krasnoyarsk&appid=da8eff3043fc441cca70712be72d110b&units=metric HTTP/1.1" 200 523
DEBUG:urllib3.connectionpool:Starting new HTTPS connection (1): api.openweathermap.org:443
DEBUG:urllib3.connectionpool:https://api.openweathermap.org:443 "GET /data/2.5/weather?q=Krasnoyarsk&appid=da8eff3043fc441cca70712be72d110b&units=metric HTTP/1.1" 200 523
DEBUG:urllib3.connectionpool:Starting new HTTPS connection (1): api.openweathermap.org:443
DEBUG:urllib3.connectionpool:https://api.openweathermap.org:443 "GET /data/2.5/weather?q=Krasnoyarsk&appid=da8eff3043fc441cca70712be72d110b&units=metric HTTP/1.1" 200 523
INFO:django.utils.autoreload:/Users/ivansizov/Documents/work/WeatherProject/WeatherProject/src/wardrobe/services/outfit_generation_logic.py changed, reloading.
DEBUG:urllib3.connectionpool:Starting new HTTPS connection (1): api.openweathermap.org:443
DEBUG:urllib3.connectionpool:https://api.openweathermap.org:443 "GET /data/2.5/weather?q=Krasnoyarsk&appid=da8eff3043fc441cca70712be72d110b&units=metric HTTP/1.1" 200 523
INFO:django.utils.autoreload:/Users/ivansizov/Documents/work/WeatherProject/WeatherProject/src/wardrobe/services/outfit_generation_logic.py changed, reloading.
DEBUG:urllib3.connectionpool:Starting new HTTPS connection (1): api.openweathermap.org:443
DEBUG:urllib3.connectionpool:https://api.openweathermap.org:443 "GET /data/2.5/weather?q=Krasnoyarsk&appid=da8eff3043fc441cca70712be72d110b&units=metric HTTP/1.1" 200 523
INFO:django.utils.autoreload:/Users/ivansizov/Documents/work/WeatherProject/WeatherProject/src/wardrobe/services/outfit_generation_logic.py changed, reloading.
DEBUG:urllib3.connectionpool:Starting new HTTPS connection (1): api.openweathermap.org:443
DEBUG:urllib3.connectionpool:https://api.openweathermap.org:443 "GET /data/2.5/weather?q=Krasnoyarsk&appid=da8eff3043fc441cca70712be72d110b&units=metric HTTP/1.1" 200 523
INFO:django.utils.autoreload:/Users/ivansizov/Documents/work/WeatherProject/WeatherProject/src/wardrobe/services/outfit_generation_logic.py changed, reloading.
DEBUG:urllib3.connectionpool:Starting new HTTPS connection (1): api.openweathermap.org:443
DEBUG:urllib3.connectionpool:https://api.openweathermap.org:443 "GET /data/2.5/weather?q=Krasnoyarsk&appid=da8eff3043fc441cca70712be72d110b&units=metric HTTP/1.1" 200 523
INFO:django.utils.autoreload:/Users/ivansizov/Documents/work/WeatherProject/WeatherProject/src/wardrobe/services/outfit_generation_logic.py changed, reloading.
DEBUG:urllib3.connectionpool:Starting new HTTPS connection (1): api.openweathermap.org:443
DEBUG:urllib3.connectionpool:https://api.openweathermap.org:443 "GET /data/2.5/weather?q=Krasnoyarsk&appid=da8eff3043fc441cca70712be72d110b&units=metric HTTP/1.1" 200 523
INFO:django.utils.autoreload:/Users/ivansizov/Documents/work/WeatherProject/WeatherProject/src/wardrobe/services/outfit_generation_logic.py changed, reloading.
DEBUG:urllib3.connectionpool:Starting new HTTPS connection (1): api.openweathermap.org:443
DEBUG:urllib3.connectionpool:https://api.openweathermap.org:443 "GET /data/2.5/weather?q=Krasnoyarsk&appid=da8eff3043fc441cca70712be72d110b&units=metric HTTP/1.1" 200 523
INFO:django.utils.autoreload:/Users/ivansizov/Documents/work/WeatherProject/WeatherProject/src/wardrobe/services/outfit_generation_logic.py changed, reloading.
DEBUG:urllib3.connectionpool:Starting new HTTPS connection (1): api.openweathermap.org:443
DEBUG:urllib3.connectionpool:https://api.openweathermap.org:443 "GET /data/2.5/weather?q=Krasnoyarsk&appid=da8eff3043fc441cca70712be72d110b&units=metric HTTP/1.1" 200 523
INFO:django.utils.autoreload:/Users/ivansizov/Documents/work/WeatherProject/WeatherProject/src/wardrobe/services/outfit_generation_logic.py changed, reloading.
INFO:django.utils.autoreload:/Users/ivansizov/Documents/work/WeatherProject/WeatherProject/src/wardrobe/services/outfit_generation_logic.py changed, reloading.
INFO:django.utils.autoreload:/Users/ivansizov/Documents/work/WeatherProject/WeatherProject/src/wardrobe/services/outfit_generation_logic.py changed, reloading.
INFO:django.utils.autoreload:/Users/ivansizov/Documents/work/WeatherProject/WeatherProject/src/wardrobe/services/outfit_generation_logic.py changed, reloading.
INFO:django.utils.autoreload:/Users/ivansizov/Documents/work/WeatherProject/WeatherProject/src/wardrobe/services/outfit_generation_logic.py changed, reloading.
INFO:django.utils.autoreload:/Users/ivansizov/Documents/work/WeatherProject/WeatherProject/src/wardrobe/services/outfit_generation_logic.py changed, reloading.
INFO:django.utils.autoreload:/Users/ivansizov/Documents/work/WeatherProject/WeatherProject/src/wardrobe/services/outfit_generation_logic.py changed, reloading.
INFO:django.utils.autoreload:/Users/ivansizov/Documents/work/WeatherProject/WeatherProject/src/wardrobe/services/outfit_generation_logic.py changed, reloading.
INFO:django.utils.autoreload:/Users/ivansizov/Documents/work/WeatherProject/WeatherProject/src/wardrobe/services/outfit_generation_logic.py changed, reloading.
INFO:django.utils.autoreload:/Users/ivansizov/Documents/work/WeatherProject/WeatherProject/src/wardrobe/services/outfit_generation_logic.py changed, reloading.
INFO:django.utils.autoreload:/Users/ivansizov/Documents/work/WeatherProject/WeatherProject/src/wardrobe/services/outfit_generation_logic.py changed, reloading.
DEBUG:urllib3.connectionpool:Starting new HTTPS connection (1): api.openweathermap.org:443
DEBUG:urllib3.connectionpool:https://api.openweathermap.org:443 "GET /data/2.5/weather?q=Krasnoyarsk&appid=da8eff3043fc441cca70712be72d110b&units=metric HTTP/1.1" 200 523
DEBUG:urllib3.connectionpool:Starting new HTTPS connection (1): api.openweathermap.org:443
DEBUG:urllib3.connectionpool:https://api.openweathermap.org:443 "GET /data/2.5/weather?q=Krasnoyarsk&appid=da8eff3043fc441cca70712be72d110b&units=metric HTTP/1.1" 200 523
DEBUG:urllib3.connectionpool:Starting new HTTPS connection (1): api.openweathermap.org:443
DEBUG:urllib3.connectionpool:https://api.openweathermap.org:443 "GET /data/2.5/weather?q=Krasnoyarsk&appid=da8eff3043fc441cca70712be72d110b&units=metric HTTP/1.1" 200 523
INFO:django.utils.autoreload:/Users/ivansizov/Documents/work/WeatherProject/WeatherProject/src/client/views.py changed, reloading.
ERROR:django.request:Internal Server Error: /profile/city/save
Traceback (most recent call last):
  File "/Users/ivansizov/Documents/work/WeatherProject/venv/lib/python3.9/site-packages/django/core/handlers/exception.py", line 55, in inner
    response = get_response(request)
  File "/Users/ivansizov/Documents/work/WeatherProject/venv/lib/python3.9/site-packages/django/core/handlers/base.py", line 197, in _get_response
    response = wrapped_callback(request, *callback_args, **callback_kwargs)
  File "/Users/ivansizov/Documents/work/WeatherProject/WeatherProject/src/client/views.py", line 45, in get_city_for_client_view
    return render(request, 'weather/settings.html')
  File "/Users/ivansizov/Documents/work/WeatherProject/venv/lib/python3.9/site-packages/django/shortcuts.py", line 24, in render
    content = loader.render_to_string(template_name, context, request, using=using)
  File "/Users/ivansizov/Documents/work/WeatherProject/venv/lib/python3.9/site-packages/django/template/loader.py", line 61, in render_to_string
    template = get_template(template_name, using=using)
  File "/Users/ivansizov/Documents/work/WeatherProject/venv/lib/python3.9/site-packages/django/template/loader.py", line 19, in get_template
    raise TemplateDoesNotExist(template_name, chain=chain)
django.template.exceptions.TemplateDoesNotExist: weather/settings.html
INFO:django.utils.autoreload:/Users/ivansizov/Documents/work/WeatherProject/WeatherProject/src/client/views.py changed, reloading.
DEBUG:urllib3.connectionpool:Starting new HTTPS connection (1): api.openweathermap.org:443
DEBUG:urllib3.connectionpool:https://api.openweathermap.org:443 "GET /data/2.5/weather?q=Kazan&appid=da8eff3043fc441cca70712be72d110b&units=metric HTTP/1.1" 200 525
WARNING:django.request:Not Found: /
WARNING:django.request:Not Found: /favicon.ico
DEBUG:urllib3.connectionpool:Starting new HTTPS connection (1): api.openweathermap.org:443
ERROR:django.request:Internal Server Error: /profile/
Traceback (most recent call last):
  File "/Users/ivansizov/Documents/work/WeatherProject/venv/lib/python3.9/site-packages/urllib3/connection.py", line 174, in _new_conn
    conn = connection.create_connection(
  File "/Users/ivansizov/Documents/work/WeatherProject/venv/lib/python3.9/site-packages/urllib3/util/connection.py", line 72, in create_connection
    for res in socket.getaddrinfo(host, port, family, socket.SOCK_STREAM):
  File "/Library/Frameworks/Python.framework/Versions/3.9/lib/python3.9/socket.py", line 954, in getaddrinfo
    for res in _socket.getaddrinfo(host, port, family, type, proto, flags):
socket.gaierror: [Errno 8] nodename nor servname provided, or not known

During handling of the above exception, another exception occurred:

Traceback (most recent call last):
  File "/Users/ivansizov/Documents/work/WeatherProject/venv/lib/python3.9/site-packages/urllib3/connectionpool.py", line 714, in urlopen
    httplib_response = self._make_request(
  File "/Users/ivansizov/Documents/work/WeatherProject/venv/lib/python3.9/site-packages/urllib3/connectionpool.py", line 403, in _make_request
    self._validate_conn(conn)
  File "/Users/ivansizov/Documents/work/WeatherProject/venv/lib/python3.9/site-packages/urllib3/connectionpool.py", line 1053, in _validate_conn
    conn.connect()
  File "/Users/ivansizov/Documents/work/WeatherProject/venv/lib/python3.9/site-packages/urllib3/connection.py", line 363, in connect
    self.sock = conn = self._new_conn()
  File "/Users/ivansizov/Documents/work/WeatherProject/venv/lib/python3.9/site-packages/urllib3/connection.py", line 186, in _new_conn
    raise NewConnectionError(
urllib3.exceptions.NewConnectionError: <urllib3.connection.HTTPSConnection object at 0x10827a0a0>: Failed to establish a new connection: [Errno 8] nodename nor servname provided, or not known

During handling of the above exception, another exception occurred:

Traceback (most recent call last):
  File "/Users/ivansizov/Documents/work/WeatherProject/venv/lib/python3.9/site-packages/requests/adapters.py", line 486, in send
    resp = conn.urlopen(
  File "/Users/ivansizov/Documents/work/WeatherProject/venv/lib/python3.9/site-packages/urllib3/connectionpool.py", line 798, in urlopen
    retries = retries.increment(
  File "/Users/ivansizov/Documents/work/WeatherProject/venv/lib/python3.9/site-packages/urllib3/util/retry.py", line 592, in increment
    raise MaxRetryError(_pool, url, error or ResponseError(cause))
urllib3.exceptions.MaxRetryError: HTTPSConnectionPool(host='api.openweathermap.org', port=443): Max retries exceeded with url: /data/2.5/weather?q=Kazan&appid=da8eff3043fc441cca70712be72d110b&units=metric (Caused by NewConnectionError('<urllib3.connection.HTTPSConnection object at 0x10827a0a0>: Failed to establish a new connection: [Errno 8] nodename nor servname provided, or not known'))

During handling of the above exception, another exception occurred:

Traceback (most recent call last):
  File "/Users/ivansizov/Documents/work/WeatherProject/venv/lib/python3.9/site-packages/django/core/handlers/exception.py", line 55, in inner
    response = get_response(request)
  File "/Users/ivansizov/Documents/work/WeatherProject/venv/lib/python3.9/site-packages/django/core/handlers/base.py", line 197, in _get_response
    response = wrapped_callback(request, *callback_args, **callback_kwargs)
  File "/Users/ivansizov/Documents/work/WeatherProject/venv/lib/python3.9/site-packages/django/contrib/auth/decorators.py", line 23, in _wrapped_view
    return view_func(request, *args, **kwargs)
  File "/Users/ivansizov/Documents/work/WeatherProject/WeatherProject/src/client/views.py", line 13, in profile
    _, _, weather_data = fetch_weather_logic(request, user)
  File "/Users/ivansizov/Documents/work/WeatherProject/WeatherProject/src/weather/services/fetch_weather_logic.py", line 17, in fetch_weather_logic
    response = requests.get(
  File "/Users/ivansizov/Documents/work/WeatherProject/venv/lib/python3.9/site-packages/requests/api.py", line 73, in get
    return request("get", url, params=params, **kwargs)
  File "/Users/ivansizov/Documents/work/WeatherProject/venv/lib/python3.9/site-packages/requests/api.py", line 59, in request
    return session.request(method=method, url=url, **kwargs)
  File "/Users/ivansizov/Documents/work/WeatherProject/venv/lib/python3.9/site-packages/requests/sessions.py", line 589, in request
    resp = self.send(prep, **send_kwargs)
  File "/Users/ivansizov/Documents/work/WeatherProject/venv/lib/python3.9/site-packages/requests/sessions.py", line 703, in send
    r = adapter.send(request, **kwargs)
  File "/Users/ivansizov/Documents/work/WeatherProject/venv/lib/python3.9/site-packages/requests/adapters.py", line 519, in send
    raise ConnectionError(e, request=request)
requests.exceptions.ConnectionError: HTTPSConnectionPool(host='api.openweathermap.org', port=443): Max retries exceeded with url: /data/2.5/weather?q=Kazan&appid=da8eff3043fc441cca70712be72d110b&units=metric (Caused by NewConnectionError('<urllib3.connection.HTTPSConnection object at 0x10827a0a0>: Failed to establish a new connection: [Errno 8] nodename nor servname provided, or not known'))
DEBUG:urllib3.connectionpool:Starting new HTTPS connection (1): api.openweathermap.org:443
ERROR:django.request:Internal Server Error: /profile/
Traceback (most recent call last):
  File "/Users/ivansizov/Documents/work/WeatherProject/venv/lib/python3.9/site-packages/urllib3/connection.py", line 174, in _new_conn
    conn = connection.create_connection(
  File "/Users/ivansizov/Documents/work/WeatherProject/venv/lib/python3.9/site-packages/urllib3/util/connection.py", line 72, in create_connection
    for res in socket.getaddrinfo(host, port, family, socket.SOCK_STREAM):
  File "/Library/Frameworks/Python.framework/Versions/3.9/lib/python3.9/socket.py", line 954, in getaddrinfo
    for res in _socket.getaddrinfo(host, port, family, type, proto, flags):
socket.gaierror: [Errno 8] nodename nor servname provided, or not known

During handling of the above exception, another exception occurred:

Traceback (most recent call last):
  File "/Users/ivansizov/Documents/work/WeatherProject/venv/lib/python3.9/site-packages/urllib3/connectionpool.py", line 714, in urlopen
    httplib_response = self._make_request(
  File "/Users/ivansizov/Documents/work/WeatherProject/venv/lib/python3.9/site-packages/urllib3/connectionpool.py", line 403, in _make_request
    self._validate_conn(conn)
  File "/Users/ivansizov/Documents/work/WeatherProject/venv/lib/python3.9/site-packages/urllib3/connectionpool.py", line 1053, in _validate_conn
    conn.connect()
  File "/Users/ivansizov/Documents/work/WeatherProject/venv/lib/python3.9/site-packages/urllib3/connection.py", line 363, in connect
    self.sock = conn = self._new_conn()
  File "/Users/ivansizov/Documents/work/WeatherProject/venv/lib/python3.9/site-packages/urllib3/connection.py", line 186, in _new_conn
    raise NewConnectionError(
urllib3.exceptions.NewConnectionError: <urllib3.connection.HTTPSConnection object at 0x1084acc10>: Failed to establish a new connection: [Errno 8] nodename nor servname provided, or not known

During handling of the above exception, another exception occurred:

Traceback (most recent call last):
  File "/Users/ivansizov/Documents/work/WeatherProject/venv/lib/python3.9/site-packages/requests/adapters.py", line 486, in send
    resp = conn.urlopen(
  File "/Users/ivansizov/Documents/work/WeatherProject/venv/lib/python3.9/site-packages/urllib3/connectionpool.py", line 798, in urlopen
    retries = retries.increment(
  File "/Users/ivansizov/Documents/work/WeatherProject/venv/lib/python3.9/site-packages/urllib3/util/retry.py", line 592, in increment
    raise MaxRetryError(_pool, url, error or ResponseError(cause))
urllib3.exceptions.MaxRetryError: HTTPSConnectionPool(host='api.openweathermap.org', port=443): Max retries exceeded with url: /data/2.5/weather?q=Kazan&appid=da8eff3043fc441cca70712be72d110b&units=metric (Caused by NewConnectionError('<urllib3.connection.HTTPSConnection object at 0x1084acc10>: Failed to establish a new connection: [Errno 8] nodename nor servname provided, or not known'))

During handling of the above exception, another exception occurred:

Traceback (most recent call last):
  File "/Users/ivansizov/Documents/work/WeatherProject/venv/lib/python3.9/site-packages/django/core/handlers/exception.py", line 55, in inner
    response = get_response(request)
  File "/Users/ivansizov/Documents/work/WeatherProject/venv/lib/python3.9/site-packages/django/core/handlers/base.py", line 197, in _get_response
    response = wrapped_callback(request, *callback_args, **callback_kwargs)
  File "/Users/ivansizov/Documents/work/WeatherProject/venv/lib/python3.9/site-packages/django/contrib/auth/decorators.py", line 23, in _wrapped_view
    return view_func(request, *args, **kwargs)
  File "/Users/ivansizov/Documents/work/WeatherProject/WeatherProject/src/client/views.py", line 13, in profile
    _, _, weather_data = fetch_weather_logic(request, user)
  File "/Users/ivansizov/Documents/work/WeatherProject/WeatherProject/src/weather/services/fetch_weather_logic.py", line 17, in fetch_weather_logic
    response = requests.get(
  File "/Users/ivansizov/Documents/work/WeatherProject/venv/lib/python3.9/site-packages/requests/api.py", line 73, in get
    return request("get", url, params=params, **kwargs)
  File "/Users/ivansizov/Documents/work/WeatherProject/venv/lib/python3.9/site-packages/requests/api.py", line 59, in request
    return session.request(method=method, url=url, **kwargs)
  File "/Users/ivansizov/Documents/work/WeatherProject/venv/lib/python3.9/site-packages/requests/sessions.py", line 589, in request
    resp = self.send(prep, **send_kwargs)
  File "/Users/ivansizov/Documents/work/WeatherProject/venv/lib/python3.9/site-packages/requests/sessions.py", line 703, in send
    r = adapter.send(request, **kwargs)
  File "/Users/ivansizov/Documents/work/WeatherProject/venv/lib/python3.9/site-packages/requests/adapters.py", line 519, in send
    raise ConnectionError(e, request=request)
requests.exceptions.ConnectionError: HTTPSConnectionPool(host='api.openweathermap.org', port=443): Max retries exceeded with url: /data/2.5/weather?q=Kazan&appid=da8eff3043fc441cca70712be72d110b&units=metric (Caused by NewConnectionError('<urllib3.connection.HTTPSConnection object at 0x1084acc10>: Failed to establish a new connection: [Errno 8] nodename nor servname provided, or not known'))
DEBUG:urllib3.connectionpool:Starting new HTTPS connection (1): api.openweathermap.org:443
ERROR:django.request:Internal Server Error: /profile/
Traceback (most recent call last):
  File "/Users/ivansizov/Documents/work/WeatherProject/venv/lib/python3.9/site-packages/urllib3/connection.py", line 174, in _new_conn
    conn = connection.create_connection(
  File "/Users/ivansizov/Documents/work/WeatherProject/venv/lib/python3.9/site-packages/urllib3/util/connection.py", line 72, in create_connection
    for res in socket.getaddrinfo(host, port, family, socket.SOCK_STREAM):
  File "/Library/Frameworks/Python.framework/Versions/3.9/lib/python3.9/socket.py", line 954, in getaddrinfo
    for res in _socket.getaddrinfo(host, port, family, type, proto, flags):
socket.gaierror: [Errno 8] nodename nor servname provided, or not known

During handling of the above exception, another exception occurred:

Traceback (most recent call last):
  File "/Users/ivansizov/Documents/work/WeatherProject/venv/lib/python3.9/site-packages/urllib3/connectionpool.py", line 714, in urlopen
    httplib_response = self._make_request(
  File "/Users/ivansizov/Documents/work/WeatherProject/venv/lib/python3.9/site-packages/urllib3/connectionpool.py", line 403, in _make_request
    self._validate_conn(conn)
  File "/Users/ivansizov/Documents/work/WeatherProject/venv/lib/python3.9/site-packages/urllib3/connectionpool.py", line 1053, in _validate_conn
    conn.connect()
  File "/Users/ivansizov/Documents/work/WeatherProject/venv/lib/python3.9/site-packages/urllib3/connection.py", line 363, in connect
    self.sock = conn = self._new_conn()
  File "/Users/ivansizov/Documents/work/WeatherProject/venv/lib/python3.9/site-packages/urllib3/connection.py", line 186, in _new_conn
    raise NewConnectionError(
urllib3.exceptions.NewConnectionError: <urllib3.connection.HTTPSConnection object at 0x10a38e790>: Failed to establish a new connection: [Errno 8] nodename nor servname provided, or not known

During handling of the above exception, another exception occurred:

Traceback (most recent call last):
  File "/Users/ivansizov/Documents/work/WeatherProject/venv/lib/python3.9/site-packages/requests/adapters.py", line 486, in send
    resp = conn.urlopen(
  File "/Users/ivansizov/Documents/work/WeatherProject/venv/lib/python3.9/site-packages/urllib3/connectionpool.py", line 798, in urlopen
    retries = retries.increment(
  File "/Users/ivansizov/Documents/work/WeatherProject/venv/lib/python3.9/site-packages/urllib3/util/retry.py", line 592, in increment
    raise MaxRetryError(_pool, url, error or ResponseError(cause))
urllib3.exceptions.MaxRetryError: HTTPSConnectionPool(host='api.openweathermap.org', port=443): Max retries exceeded with url: /data/2.5/weather?q=Kazan&appid=da8eff3043fc441cca70712be72d110b&units=metric (Caused by NewConnectionError('<urllib3.connection.HTTPSConnection object at 0x10a38e790>: Failed to establish a new connection: [Errno 8] nodename nor servname provided, or not known'))

During handling of the above exception, another exception occurred:

Traceback (most recent call last):
  File "/Users/ivansizov/Documents/work/WeatherProject/venv/lib/python3.9/site-packages/django/core/handlers/exception.py", line 55, in inner
    response = get_response(request)
  File "/Users/ivansizov/Documents/work/WeatherProject/venv/lib/python3.9/site-packages/django/core/handlers/base.py", line 197, in _get_response
    response = wrapped_callback(request, *callback_args, **callback_kwargs)
  File "/Users/ivansizov/Documents/work/WeatherProject/venv/lib/python3.9/site-packages/django/contrib/auth/decorators.py", line 23, in _wrapped_view
    return view_func(request, *args, **kwargs)
  File "/Users/ivansizov/Documents/work/WeatherProject/WeatherProject/src/client/views.py", line 13, in profile
    _, _, weather_data = fetch_weather_logic(request, user)
  File "/Users/ivansizov/Documents/work/WeatherProject/WeatherProject/src/weather/services/fetch_weather_logic.py", line 17, in fetch_weather_logic
    response = requests.get(
  File "/Users/ivansizov/Documents/work/WeatherProject/venv/lib/python3.9/site-packages/requests/api.py", line 73, in get
    return request("get", url, params=params, **kwargs)
  File "/Users/ivansizov/Documents/work/WeatherProject/venv/lib/python3.9/site-packages/requests/api.py", line 59, in request
    return session.request(method=method, url=url, **kwargs)
  File "/Users/ivansizov/Documents/work/WeatherProject/venv/lib/python3.9/site-packages/requests/sessions.py", line 589, in request
    resp = self.send(prep, **send_kwargs)
  File "/Users/ivansizov/Documents/work/WeatherProject/venv/lib/python3.9/site-packages/requests/sessions.py", line 703, in send
    r = adapter.send(request, **kwargs)
  File "/Users/ivansizov/Documents/work/WeatherProject/venv/lib/python3.9/site-packages/requests/adapters.py", line 519, in send
    raise ConnectionError(e, request=request)
requests.exceptions.ConnectionError: HTTPSConnectionPool(host='api.openweathermap.org', port=443): Max retries exceeded with url: /data/2.5/weather?q=Kazan&appid=da8eff3043fc441cca70712be72d110b&units=metric (Caused by NewConnectionError('<urllib3.connection.HTTPSConnection object at 0x10a38e790>: Failed to establish a new connection: [Errno 8] nodename nor servname provided, or not known'))
DEBUG:urllib3.connectionpool:Starting new HTTPS connection (1): api.openweathermap.org:443
DEBUG:urllib3.connectionpool:https://api.openweathermap.org:443 "GET /data/2.5/weather?q=Kazan&appid=da8eff3043fc441cca70712be72d110b&units=metric HTTP/1.1" 200 515
DEBUG:urllib3.connectionpool:Starting new HTTPS connection (1): api.openweathermap.org:443
DEBUG:urllib3.connectionpool:https://api.openweathermap.org:443 "GET /data/2.5/weather?q=Kazan&appid=da8eff3043fc441cca70712be72d110b&units=metric HTTP/1.1" 200 515
DEBUG:urllib3.connectionpool:Starting new HTTPS connection (1): api.openweathermap.org:443
DEBUG:urllib3.connectionpool:Starting new HTTPS connection (1): api.openweathermap.org:443
DEBUG:urllib3.connectionpool:https://api.openweathermap.org:443 "GET /data/2.5/weather?q=Kazan&appid=da8eff3043fc441cca70712be72d110b&units=metric HTTP/1.1" 200 515
DEBUG:urllib3.connectionpool:https://api.openweathermap.org:443 "GET /data/2.5/weather?q=Kazan&appid=da8eff3043fc441cca70712be72d110b&units=metric HTTP/1.1" 200 515
DEBUG:urllib3.connectionpool:Starting new HTTPS connection (1): api.openweathermap.org:443
DEBUG:urllib3.connectionpool:https://api.openweathermap.org:443 "GET /data/2.5/weather?q=Kazan&appid=da8eff3043fc441cca70712be72d110b&units=metric HTTP/1.1" 200 515
DEBUG:urllib3.connectionpool:Starting new HTTPS connection (1): api.openweathermap.org:443
DEBUG:urllib3.connectionpool:https://api.openweathermap.org:443 "GET /data/2.5/weather?q=Kazan&appid=da8eff3043fc441cca70712be72d110b&units=metric HTTP/1.1" 200 515
DEBUG:urllib3.connectionpool:Starting new HTTPS connection (1): api.openweathermap.org:443
DEBUG:urllib3.connectionpool:https://api.openweathermap.org:443 "GET /data/2.5/weather?q=Kazan&appid=da8eff3043fc441cca70712be72d110b&units=metric HTTP/1.1" 200 515
DEBUG:urllib3.connectionpool:Starting new HTTPS connection (1): api.openweathermap.org:443
DEBUG:urllib3.connectionpool:https://api.openweathermap.org:443 "GET /data/2.5/weather?q=Kazan&appid=da8eff3043fc441cca70712be72d110b&units=metric HTTP/1.1" 200 515
DEBUG:urllib3.connectionpool:Starting new HTTPS connection (1): api.openweathermap.org:443
DEBUG:urllib3.connectionpool:https://api.openweathermap.org:443 "GET /data/2.5/weather?q=Baltiysk&appid=da8eff3043fc441cca70712be72d110b&units=metric HTTP/1.1" 200 521
INFO:django.utils.autoreload:/Users/ivansizov/Documents/work/WeatherProject/WeatherProject/src/client/views.py changed, reloading.
WARNING:django.request:Not Found: /
DEBUG:urllib3.connectionpool:Starting new HTTPS connection (1): api.openweathermap.org:443
DEBUG:urllib3.connectionpool:https://api.openweathermap.org:443 "GET /data/2.5/weather?q=Baltiysk&appid=da8eff3043fc441cca70712be72d110b&units=metric HTTP/1.1" 200 521
DEBUG:urllib3.connectionpool:Starting new HTTPS connection (1): api.openweathermap.org:443
DEBUG:urllib3.connectionpool:https://api.openweathermap.org:443 "GET /data/2.5/weather?q=Baltiysk&appid=da8eff3043fc441cca70712be72d110b&units=metric HTTP/1.1" 200 521
DEBUG:urllib3.connectionpool:Starting new HTTPS connection (1): api.openweathermap.org:443
DEBUG:urllib3.connectionpool:https://api.openweathermap.org:443 "GET /data/2.5/weather?q=Baltiysk&appid=da8eff3043fc441cca70712be72d110b&units=metric HTTP/1.1" 200 521
DEBUG:urllib3.connectionpool:Starting new HTTPS connection (1): api.openweathermap.org:443
DEBUG:urllib3.connectionpool:https://api.openweathermap.org:443 "GET /data/2.5/weather?q=Baltiysk&appid=da8eff3043fc441cca70712be72d110b&units=metric HTTP/1.1" 200 521
ERROR:django.request:Internal Server Error: /profile/
Traceback (most recent call last):
  File "/Users/ivansizov/Documents/work/WeatherProject/venv/lib/python3.9/site-packages/django/core/handlers/exception.py", line 55, in inner
    response = get_response(request)
  File "/Users/ivansizov/Documents/work/WeatherProject/venv/lib/python3.9/site-packages/django/core/handlers/base.py", line 197, in _get_response
    response = wrapped_callback(request, *callback_args, **callback_kwargs)
  File "/Users/ivansizov/Documents/work/WeatherProject/venv/lib/python3.9/site-packages/django/contrib/auth/decorators.py", line 23, in _wrapped_view
    return view_func(request, *args, **kwargs)
  File "/Users/ivansizov/Documents/work/WeatherProject/WeatherProject/src/client/views.py", line 13, in profile
    client, region, city, weather_data = fetch_weather_and_client_info_logic(user)
ValueError: too many values to unpack (expected 4)
INFO:django.utils.autoreload:/Users/ivansizov/Documents/work/WeatherProject/WeatherProject/src/client/views.py changed, reloading.
DEBUG:urllib3.connectionpool:Starting new HTTPS connection (1): api.openweathermap.org:443
DEBUG:urllib3.connectionpool:https://api.openweathermap.org:443 "GET /data/2.5/weather?q=Baltiysk&appid=da8eff3043fc441cca70712be72d110b&units=metric HTTP/1.1" 200 521
DEBUG:urllib3.connectionpool:Starting new HTTPS connection (1): api.openweathermap.org:443
DEBUG:urllib3.connectionpool:https://api.openweathermap.org:443 "GET /data/2.5/weather?q=Baltiysk&appid=da8eff3043fc441cca70712be72d110b&units=metric HTTP/1.1" 200 521
DEBUG:urllib3.connectionpool:Starting new HTTPS connection (1): api.openweathermap.org:443
DEBUG:urllib3.connectionpool:https://api.openweathermap.org:443 "GET /data/2.5/weather?q=Baltiysk&appid=da8eff3043fc441cca70712be72d110b&units=metric HTTP/1.1" 200 521
DEBUG:urllib3.connectionpool:Starting new HTTPS connection (1): api.openweathermap.org:443
DEBUG:urllib3.connectionpool:https://api.openweathermap.org:443 "GET /data/2.5/weather?q=Baltiysk&appid=da8eff3043fc441cca70712be72d110b&units=metric HTTP/1.1" 200 521
DEBUG:urllib3.connectionpool:Starting new HTTPS connection (1): api.openweathermap.org:443
DEBUG:urllib3.connectionpool:https://api.openweathermap.org:443 "GET /data/2.5/weather?q=Baltiysk&appid=da8eff3043fc441cca70712be72d110b&units=metric HTTP/1.1" 200 521
DEBUG:urllib3.connectionpool:Starting new HTTPS connection (1): api.openweathermap.org:443
DEBUG:urllib3.connectionpool:https://api.openweathermap.org:443 "GET /data/2.5/weather?q=Baltiysk&appid=da8eff3043fc441cca70712be72d110b&units=metric HTTP/1.1" 200 521
DEBUG:urllib3.connectionpool:Starting new HTTPS connection (1): api.openweathermap.org:443
DEBUG:urllib3.connectionpool:https://api.openweathermap.org:443 "GET /data/2.5/weather?q=Baltiysk&appid=da8eff3043fc441cca70712be72d110b&units=metric HTTP/1.1" 200 521
INFO:django.utils.autoreload:/Users/ivansizov/Documents/work/WeatherProject/WeatherProject/src/client/views.py changed, reloading.
DEBUG:urllib3.connectionpool:Starting new HTTPS connection (1): api.openweathermap.org:443
DEBUG:urllib3.connectionpool:https://api.openweathermap.org:443 "GET /data/2.5/weather?q=Baltiysk&appid=da8eff3043fc441cca70712be72d110b&units=metric HTTP/1.1" 200 521
WARNING:django.request:Not Found: /
DEBUG:urllib3.connectionpool:Starting new HTTPS connection (1): api.openweathermap.org:443
DEBUG:urllib3.connectionpool:https://api.openweathermap.org:443 "GET /data/2.5/weather?q=Baltiysk&appid=da8eff3043fc441cca70712be72d110b&units=metric HTTP/1.1" 200 521
WARNING:django.request:Not Found: /accounts/login/
DEBUG:urllib3.connectionpool:Starting new HTTPS connection (1): github.com:443
DEBUG:urllib3.connectionpool:https://github.com:443 "POST /login/oauth/access_token HTTP/1.1" 200 None
DEBUG:urllib3.connectionpool:Starting new HTTPS connection (1): api.github.com:443
DEBUG:urllib3.connectionpool:https://api.github.com:443 "GET /user HTTP/1.1" 200 None
DEBUG:urllib3.connectionpool:Starting new HTTPS connection (1): api.github.com:443
DEBUG:urllib3.connectionpool:https://api.github.com:443 "GET /user/emails HTTP/1.1" 404 None
WARNING:django.request:Not Found: /accounts/profile/
WARNING:django.request:Not Found: /favicon.ico
DEBUG:urllib3.connectionpool:Starting new HTTPS connection (1): api.openweathermap.org:443
DEBUG:urllib3.connectionpool:https://api.openweathermap.org:443 "GET /data/2.5/weather?q=Irkutsk&appid=da8eff3043fc441cca70712be72d110b&units=metric HTTP/1.1" 200 462
INFO:django.utils.autoreload:/Users/ivansizov/Documents/work/WeatherProject/WeatherProject/src/client/services/client_city_save.py changed, reloading.
INFO:django.utils.autoreload:/Users/ivansizov/Documents/work/WeatherProject/WeatherProject/src/client/services/client_city_save.py changed, reloading.
ERROR:django.request:Internal Server Error: /profile/city/save
Traceback (most recent call last):
  File "/Users/ivansizov/Documents/work/WeatherProject/WeatherProject/src/client/services/client_city_save.py", line 10, in get_city_for_client
    client = Client.objects.get(user=user_instance).fields('region', 'city')
AttributeError: 'Client' object has no attribute 'fields'

During handling of the above exception, another exception occurred:

Traceback (most recent call last):
  File "/Users/ivansizov/Documents/work/WeatherProject/venv/lib/python3.9/site-packages/django/db/backends/utils.py", line 89, in _execute
    return self.cursor.execute(sql, params)
  File "/Users/ivansizov/Documents/work/WeatherProject/venv/lib/python3.9/site-packages/django/db/backends/sqlite3/base.py", line 357, in execute
    return Database.Cursor.execute(self, query, params)
sqlite3.IntegrityError: UNIQUE constraint failed: client_client.user_id

The above exception was the direct cause of the following exception:

Traceback (most recent call last):
  File "/Users/ivansizov/Documents/work/WeatherProject/venv/lib/python3.9/site-packages/django/core/handlers/exception.py", line 55, in inner
    response = get_response(request)
  File "/Users/ivansizov/Documents/work/WeatherProject/venv/lib/python3.9/site-packages/django/core/handlers/base.py", line 197, in _get_response
    response = wrapped_callback(request, *callback_args, **callback_kwargs)
  File "/Users/ivansizov/Documents/work/WeatherProject/WeatherProject/src/client/views.py", line 41, in get_city_for_client_view
    get_city_for_client(request)
  File "/Users/ivansizov/Documents/work/WeatherProject/WeatherProject/src/client/services/client_city_save.py", line 17, in get_city_for_client
    client.save()
  File "/Users/ivansizov/Documents/work/WeatherProject/venv/lib/python3.9/site-packages/django/db/models/base.py", line 812, in save
    self.save_base(
  File "/Users/ivansizov/Documents/work/WeatherProject/venv/lib/python3.9/site-packages/django/db/models/base.py", line 863, in save_base
    updated = self._save_table(
  File "/Users/ivansizov/Documents/work/WeatherProject/venv/lib/python3.9/site-packages/django/db/models/base.py", line 1006, in _save_table
    results = self._do_insert(
  File "/Users/ivansizov/Documents/work/WeatherProject/venv/lib/python3.9/site-packages/django/db/models/base.py", line 1047, in _do_insert
    return manager._insert(
  File "/Users/ivansizov/Documents/work/WeatherProject/venv/lib/python3.9/site-packages/django/db/models/manager.py", line 85, in manager_method
    return getattr(self.get_queryset(), name)(*args, **kwargs)
  File "/Users/ivansizov/Documents/work/WeatherProject/venv/lib/python3.9/site-packages/django/db/models/query.py", line 1791, in _insert
    return query.get_compiler(using=using).execute_sql(returning_fields)
  File "/Users/ivansizov/Documents/work/WeatherProject/venv/lib/python3.9/site-packages/django/db/models/sql/compiler.py", line 1660, in execute_sql
    cursor.execute(sql, params)
  File "/Users/ivansizov/Documents/work/WeatherProject/venv/lib/python3.9/site-packages/debug_toolbar/panels/sql/tracking.py", line 246, in execute
    return self._record(super().execute, sql, params)
  File "/Users/ivansizov/Documents/work/WeatherProject/venv/lib/python3.9/site-packages/debug_toolbar/panels/sql/tracking.py", line 167, in _record
    return method(sql, params)
  File "/Users/ivansizov/Documents/work/WeatherProject/venv/lib/python3.9/site-packages/django/db/backends/utils.py", line 67, in execute
    return self._execute_with_wrappers(
  File "/Users/ivansizov/Documents/work/WeatherProject/venv/lib/python3.9/site-packages/django/db/backends/utils.py", line 80, in _execute_with_wrappers
    return executor(sql, params, many, context)
  File "/Users/ivansizov/Documents/work/WeatherProject/venv/lib/python3.9/site-packages/django/db/backends/utils.py", line 89, in _execute
    return self.cursor.execute(sql, params)
  File "/Users/ivansizov/Documents/work/WeatherProject/venv/lib/python3.9/site-packages/django/db/utils.py", line 91, in __exit__
    raise dj_exc_value.with_traceback(traceback) from exc_value
  File "/Users/ivansizov/Documents/work/WeatherProject/venv/lib/python3.9/site-packages/django/db/backends/utils.py", line 89, in _execute
    return self.cursor.execute(sql, params)
  File "/Users/ivansizov/Documents/work/WeatherProject/venv/lib/python3.9/site-packages/django/db/backends/sqlite3/base.py", line 357, in execute
    return Database.Cursor.execute(self, query, params)
django.db.utils.IntegrityError: UNIQUE constraint failed: client_client.user_id
INFO:django.utils.autoreload:/Users/ivansizov/Documents/work/WeatherProject/WeatherProject/src/client/services/client_city_save.py changed, reloading.
INFO:django.utils.autoreload:/Users/ivansizov/Documents/work/WeatherProject/WeatherProject/src/client/services/client_city_save.py changed, reloading.
INFO:django.utils.autoreload:/Users/ivansizov/Documents/work/WeatherProject/WeatherProject/src/weather/services/fetch_weather_logic.py changed, reloading.
DEBUG:urllib3.connectionpool:Starting new HTTPS connection (1): api.openweathermap.org:443
DEBUG:urllib3.connectionpool:https://api.openweathermap.org:443 "GET /data/2.5/weather?q=Shelekhov&appid=da8eff3043fc441cca70712be72d110b&units=metric HTTP/1.1" 200 517
DEBUG:urllib3.connectionpool:Starting new HTTPS connection (1): api.openweathermap.org:443
DEBUG:urllib3.connectionpool:https://api.openweathermap.org:443 "GET /data/2.5/weather?q=Shelekhov&appid=da8eff3043fc441cca70712be72d110b&units=metric HTTP/1.1" 200 517
DEBUG:urllib3.connectionpool:Starting new HTTPS connection (1): api.openweathermap.org:443
DEBUG:urllib3.connectionpool:https://api.openweathermap.org:443 "GET /data/2.5/weather?q=Shelekhov&appid=da8eff3043fc441cca70712be72d110b&units=metric HTTP/1.1" 200 517
DEBUG:urllib3.connectionpool:Starting new HTTPS connection (1): api.openweathermap.org:443
DEBUG:urllib3.connectionpool:https://api.openweathermap.org:443 "GET /data/2.5/weather?q=Shelekhov&appid=da8eff3043fc441cca70712be72d110b&units=metric HTTP/1.1" 200 517
INFO:django.utils.autoreload:/Users/ivansizov/Documents/work/WeatherProject/WeatherProject/src/wardrobe/services/outfit_generation_logic.py changed, reloading.
INFO:django.utils.autoreload:/Users/ivansizov/Documents/work/WeatherProject/WeatherProject/src/wardrobe/services/outfit_generation_logic.py changed, reloading.
INFO:django.utils.autoreload:/Users/ivansizov/Documents/work/WeatherProject/WeatherProject/src/wardrobe/services/outfit_generation_logic.py changed, reloading.
INFO:django.utils.autoreload:/Users/ivansizov/Documents/work/WeatherProject/WeatherProject/src/wardrobe/services/outfit_generation_logic.py changed, reloading.
INFO:django.utils.autoreload:/Users/ivansizov/Documents/work/WeatherProject/WeatherProject/src/wardrobe/services/outfit_generation_logic.py changed, reloading.
INFO:django.utils.autoreload:/Users/ivansizov/Documents/work/WeatherProject/WeatherProject/src/wardrobe/services/outfit_generation_logic.py changed, reloading.
INFO:django.utils.autoreload:/Users/ivansizov/Documents/work/WeatherProject/WeatherProject/src/wardrobe/services/outfit_generation_logic.py changed, reloading.
DEBUG:urllib3.connectionpool:Starting new HTTPS connection (1): api.openweathermap.org:443
DEBUG:urllib3.connectionpool:https://api.openweathermap.org:443 "GET /data/2.5/weather?q=Shelekhov&appid=da8eff3043fc441cca70712be72d110b&units=metric HTTP/1.1" 200 517
INFO:django.utils.autoreload:/Users/ivansizov/Documents/work/WeatherProject/WeatherProject/src/wardrobe/services/outfit_generation_logic.py changed, reloading.
INFO:django.utils.autoreload:/Users/ivansizov/Documents/work/WeatherProject/WeatherProject/src/wardrobe/services/outfit_generation_logic.py changed, reloading.
DEBUG:urllib3.connectionpool:Starting new HTTPS connection (1): api.openweathermap.org:443
DEBUG:urllib3.connectionpool:https://api.openweathermap.org:443 "GET /data/2.5/weather?q=Shelekhov&appid=da8eff3043fc441cca70712be72d110b&units=metric HTTP/1.1" 200 517
ERROR:django.request:Internal Server Error: /weather/
Traceback (most recent call last):
  File "/Users/ivansizov/Documents/work/WeatherProject/venv/lib/python3.9/site-packages/django/core/handlers/exception.py", line 55, in inner
    response = get_response(request)
  File "/Users/ivansizov/Documents/work/WeatherProject/venv/lib/python3.9/site-packages/django/core/handlers/base.py", line 197, in _get_response
    response = wrapped_callback(request, *callback_args, **callback_kwargs)
  File "/Users/ivansizov/Documents/work/WeatherProject/WeatherProject/src/weather/views.py", line 20, in fetch_weather
    clothes_list_2 = outfit_logic(user, temperature, style_id)
  File "/Users/ivansizov/Documents/work/WeatherProject/WeatherProject/src/wardrobe/services/outfit_generation_logic.py", line 113, in outfit_logic
    fill_clothes_list(filtered_clothes_by_style, temperature, clothes_list)
  File "/Users/ivansizov/Documents/work/WeatherProject/WeatherProject/src/wardrobe/services/outfit_generation_logic.py", line 68, in fill_clothes_list
    for item in clothes:
  File "/Users/ivansizov/Documents/work/WeatherProject/venv/lib/python3.9/site-packages/django/db/models/query.py", line 394, in __iter__
    self._fetch_all()
  File "/Users/ivansizov/Documents/work/WeatherProject/venv/lib/python3.9/site-packages/django/db/models/query.py", line 1867, in _fetch_all
    self._result_cache = list(self._iterable_class(self))
  File "/Users/ivansizov/Documents/work/WeatherProject/venv/lib/python3.9/site-packages/django/db/models/query.py", line 87, in __iter__
    results = compiler.execute_sql(
  File "/Users/ivansizov/Documents/work/WeatherProject/venv/lib/python3.9/site-packages/django/db/models/sql/compiler.py", line 1385, in execute_sql
    sql, params = self.as_sql()
  File "/Users/ivansizov/Documents/work/WeatherProject/venv/lib/python3.9/site-packages/django/db/models/sql/compiler.py", line 593, in as_sql
    extra_select, order_by, group_by = self.pre_sql_setup()
  File "/Users/ivansizov/Documents/work/WeatherProject/venv/lib/python3.9/site-packages/django/db/models/sql/compiler.py", line 71, in pre_sql_setup
    self.setup_query()
  File "/Users/ivansizov/Documents/work/WeatherProject/venv/lib/python3.9/site-packages/django/db/models/sql/compiler.py", line 62, in setup_query
    self.select, self.klass_info, self.annotation_col_map = self.get_select()
  File "/Users/ivansizov/Documents/work/WeatherProject/venv/lib/python3.9/site-packages/django/db/models/sql/compiler.py", line 278, in get_select
    related_klass_infos = self.get_related_selections(select)
  File "/Users/ivansizov/Documents/work/WeatherProject/venv/lib/python3.9/site-packages/django/db/models/sql/compiler.py", line 1061, in get_related_selections
    if not select_related_descend(
  File "/Users/ivansizov/Documents/work/WeatherProject/venv/lib/python3.9/site-packages/django/db/models/query_utils.py", line 304, in select_related_descend
    raise FieldError(msg)
django.core.exceptions.FieldError: Field Clothes.type_of_clothes cannot be both deferred and traversed using select_related at the same time.
INFO:django.utils.autoreload:/Users/ivansizov/Documents/work/WeatherProject/WeatherProject/src/wardrobe/services/outfit_generation_logic.py changed, reloading.
INFO:django.utils.autoreload:/Users/ivansizov/Documents/work/WeatherProject/WeatherProject/src/wardrobe/services/outfit_generation_logic.py changed, reloading.
DEBUG:urllib3.connectionpool:Starting new HTTPS connection (1): api.openweathermap.org:443
DEBUG:urllib3.connectionpool:https://api.openweathermap.org:443 "GET /data/2.5/weather?q=Shelekhov&appid=da8eff3043fc441cca70712be72d110b&units=metric HTTP/1.1" 200 517
INFO:django.utils.autoreload:/Users/ivansizov/Documents/work/WeatherProject/WeatherProject/src/wardrobe/services/outfit_generation_logic.py changed, reloading.
INFO:django.utils.autoreload:/Users/ivansizov/Documents/work/WeatherProject/WeatherProject/src/wardrobe/services/outfit_generation_logic.py changed, reloading.
DEBUG:urllib3.connectionpool:Starting new HTTPS connection (1): api.openweathermap.org:443
DEBUG:urllib3.connectionpool:https://api.openweathermap.org:443 "GET /data/2.5/weather?q=Shelekhov&appid=da8eff3043fc441cca70712be72d110b&units=metric HTTP/1.1" 200 517
ERROR:root:An error occurred: Cannot call select_related() after .values() or .values_list()
ERROR:django.request:Internal Server Error: /weather/
Traceback (most recent call last):
  File "/Users/ivansizov/Documents/work/WeatherProject/venv/lib/python3.9/site-packages/django/core/handlers/exception.py", line 55, in inner
    response = get_response(request)
  File "/Users/ivansizov/Documents/work/WeatherProject/venv/lib/python3.9/site-packages/django/core/handlers/base.py", line 197, in _get_response
    response = wrapped_callback(request, *callback_args, **callback_kwargs)
  File "/Users/ivansizov/Documents/work/WeatherProject/WeatherProject/src/weather/views.py", line 20, in fetch_weather
    clothes_list_2 = outfit_logic(user, temperature, style_id)
  File "/Users/ivansizov/Documents/work/WeatherProject/WeatherProject/src/wardrobe/services/outfit_generation_logic.py", line 122, in outfit_logic
    filtered_clothes_by_style = sort_clothes_by_style(clothes, style)
  File "/Users/ivansizov/Documents/work/WeatherProject/WeatherProject/src/wardrobe/services/outfit_generation_logic.py", line 71, in sort_clothes_by_style
    return clothes.filter(style__name=style)
AttributeError: 'NoneType' object has no attribute 'filter'
DEBUG:urllib3.connectionpool:Starting new HTTPS connection (1): api.openweathermap.org:443
INFO:django.utils.autoreload:/Users/ivansizov/Documents/work/WeatherProject/WeatherProject/src/wardrobe/services/outfit_generation_logic.py changed, reloading.
DEBUG:urllib3.connectionpool:Starting new HTTPS connection (1): api.openweathermap.org:443
DEBUG:urllib3.connectionpool:https://api.openweathermap.org:443 "GET /data/2.5/weather?q=Shelekhov&appid=da8eff3043fc441cca70712be72d110b&units=metric HTTP/1.1" 200 517
ERROR:root:An error occurred: Cannot call select_related() after .values() or .values_list()
ERROR:django.request:Internal Server Error: /weather/
Traceback (most recent call last):
  File "/Users/ivansizov/Documents/work/WeatherProject/venv/lib/python3.9/site-packages/django/core/handlers/exception.py", line 55, in inner
    response = get_response(request)
  File "/Users/ivansizov/Documents/work/WeatherProject/venv/lib/python3.9/site-packages/django/core/handlers/base.py", line 197, in _get_response
    response = wrapped_callback(request, *callback_args, **callback_kwargs)
  File "/Users/ivansizov/Documents/work/WeatherProject/WeatherProject/src/weather/views.py", line 20, in fetch_weather
    clothes_list_2 = outfit_logic(user, temperature, style_id)
  File "/Users/ivansizov/Documents/work/WeatherProject/WeatherProject/src/wardrobe/services/outfit_generation_logic.py", line 122, in outfit_logic
    filtered_clothes_by_style = sort_clothes_by_style(clothes, style)
  File "/Users/ivansizov/Documents/work/WeatherProject/WeatherProject/src/wardrobe/services/outfit_generation_logic.py", line 71, in sort_clothes_by_style
    return clothes.filter(style__name=style)
AttributeError: 'NoneType' object has no attribute 'filter'
DEBUG:urllib3.connectionpool:Starting new HTTPS connection (1): api.openweathermap.org:443
DEBUG:urllib3.connectionpool:https://api.openweathermap.org:443 "GET /data/2.5/weather?q=Shelekhov&appid=da8eff3043fc441cca70712be72d110b&units=metric HTTP/1.1" 200 517
ERROR:root:An error occurred: Cannot call select_related() after .values() or .values_list()
ERROR:django.request:Internal Server Error: /weather/
Traceback (most recent call last):
  File "/Users/ivansizov/Documents/work/WeatherProject/venv/lib/python3.9/site-packages/django/core/handlers/exception.py", line 55, in inner
    response = get_response(request)
  File "/Users/ivansizov/Documents/work/WeatherProject/venv/lib/python3.9/site-packages/django/core/handlers/base.py", line 197, in _get_response
    response = wrapped_callback(request, *callback_args, **callback_kwargs)
  File "/Users/ivansizov/Documents/work/WeatherProject/WeatherProject/src/weather/views.py", line 20, in fetch_weather
    clothes_list_2 = outfit_logic(user, temperature, style_id)
  File "/Users/ivansizov/Documents/work/WeatherProject/WeatherProject/src/wardrobe/services/outfit_generation_logic.py", line 122, in outfit_logic
    filtered_clothes_by_style = sort_clothes_by_style(clothes, style)
  File "/Users/ivansizov/Documents/work/WeatherProject/WeatherProject/src/wardrobe/services/outfit_generation_logic.py", line 71, in sort_clothes_by_style
    return clothes.filter(style__name=style)
AttributeError: 'NoneType' object has no attribute 'filter'
INFO:django.utils.autoreload:/Users/ivansizov/Documents/work/WeatherProject/WeatherProject/src/wardrobe/services/outfit_generation_logic.py changed, reloading.
DEBUG:urllib3.connectionpool:Starting new HTTPS connection (1): api.openweathermap.org:443
DEBUG:urllib3.connectionpool:https://api.openweathermap.org:443 "GET /data/2.5/weather?q=Shelekhov&appid=da8eff3043fc441cca70712be72d110b&units=metric HTTP/1.1" 200 517
DEBUG:urllib3.connectionpool:Starting new HTTPS connection (1): api.openweathermap.org:443
DEBUG:urllib3.connectionpool:https://api.openweathermap.org:443 "GET /data/2.5/weather?q=Shelekhov&appid=da8eff3043fc441cca70712be72d110b&units=metric HTTP/1.1" 200 517
ERROR:django.request:Internal Server Error: /weather/
Traceback (most recent call last):
  File "/Users/ivansizov/Documents/work/WeatherProject/venv/lib/python3.9/site-packages/django/core/handlers/exception.py", line 55, in inner
    response = get_response(request)
  File "/Users/ivansizov/Documents/work/WeatherProject/venv/lib/python3.9/site-packages/django/core/handlers/base.py", line 197, in _get_response
    response = wrapped_callback(request, *callback_args, **callback_kwargs)
  File "/Users/ivansizov/Documents/work/WeatherProject/WeatherProject/src/weather/views.py", line 20, in fetch_weather
    clothes_list_2 = outfit_logic(user, temperature, style_id)
  File "/Users/ivansizov/Documents/work/WeatherProject/WeatherProject/src/wardrobe/services/outfit_generation_logic.py", line 123, in outfit_logic
    fill_clothes_list(filtered_clothes_by_style, temperature, clothes_list)
  File "/Users/ivansizov/Documents/work/WeatherProject/WeatherProject/src/wardrobe/services/outfit_generation_logic.py", line 79, in fill_clothes_list
    if not clothes_list[item.type_of_clothes.type]['status']:
AttributeError: 'dict' object has no attribute 'type_of_clothes'
INFO:django.utils.autoreload:/Users/ivansizov/Documents/work/WeatherProject/WeatherProject/src/wardrobe/services/outfit_generation_logic.py changed, reloading.
DEBUG:urllib3.connectionpool:Starting new HTTPS connection (1): api.openweathermap.org:443
DEBUG:urllib3.connectionpool:https://api.openweathermap.org:443 "GET /data/2.5/weather?q=Shelekhov&appid=da8eff3043fc441cca70712be72d110b&units=metric HTTP/1.1" 200 517
ERROR:django.request:Internal Server Error: /weather/
Traceback (most recent call last):
  File "/Users/ivansizov/Documents/work/WeatherProject/venv/lib/python3.9/site-packages/django/core/handlers/exception.py", line 55, in inner
    response = get_response(request)
  File "/Users/ivansizov/Documents/work/WeatherProject/venv/lib/python3.9/site-packages/django/core/handlers/base.py", line 197, in _get_response
    response = wrapped_callback(request, *callback_args, **callback_kwargs)
  File "/Users/ivansizov/Documents/work/WeatherProject/WeatherProject/src/weather/views.py", line 20, in fetch_weather
    clothes_list_2 = outfit_logic(user, temperature, style_id)
  File "/Users/ivansizov/Documents/work/WeatherProject/WeatherProject/src/wardrobe/services/outfit_generation_logic.py", line 124, in outfit_logic
    fill_clothes_list(filtered_clothes_by_style, temperature, clothes_list)
  File "/Users/ivansizov/Documents/work/WeatherProject/WeatherProject/src/wardrobe/services/outfit_generation_logic.py", line 80, in fill_clothes_list
    if not clothes_list[item.type_of_clothes.type]['status']:
AttributeError: 'dict' object has no attribute 'type_of_clothes'
INFO:django.utils.autoreload:/Users/ivansizov/Documents/work/WeatherProject/WeatherProject/src/wardrobe/services/outfit_generation_logic.py changed, reloading.
DEBUG:urllib3.connectionpool:Starting new HTTPS connection (1): api.openweathermap.org:443
DEBUG:urllib3.connectionpool:https://api.openweathermap.org:443 "GET /data/2.5/weather?q=Shelekhov&appid=da8eff3043fc441cca70712be72d110b&units=metric HTTP/1.1" 200 517
ERROR:django.request:Internal Server Error: /weather/
Traceback (most recent call last):
  File "/Users/ivansizov/Documents/work/WeatherProject/venv/lib/python3.9/site-packages/django/core/handlers/exception.py", line 55, in inner
    response = get_response(request)
  File "/Users/ivansizov/Documents/work/WeatherProject/venv/lib/python3.9/site-packages/django/core/handlers/base.py", line 197, in _get_response
    response = wrapped_callback(request, *callback_args, **callback_kwargs)
  File "/Users/ivansizov/Documents/work/WeatherProject/WeatherProject/src/weather/views.py", line 20, in fetch_weather
    clothes_list_2 = outfit_logic(user, temperature, style_id)
  File "/Users/ivansizov/Documents/work/WeatherProject/WeatherProject/src/wardrobe/services/outfit_generation_logic.py", line 124, in outfit_logic
    fill_clothes_list(filtered_clothes_by_style, temperature, clothes_list)
  File "/Users/ivansizov/Documents/work/WeatherProject/WeatherProject/src/wardrobe/services/outfit_generation_logic.py", line 80, in fill_clothes_list
    if not clothes_list[item.type_of_clothes.type]['status']:
AttributeError: 'dict' object has no attribute 'type_of_clothes'
INFO:django.utils.autoreload:/Users/ivansizov/Documents/work/WeatherProject/WeatherProject/src/wardrobe/services/outfit_generation_logic.py changed, reloading.
DEBUG:urllib3.connectionpool:Starting new HTTPS connection (1): api.openweathermap.org:443
DEBUG:urllib3.connectionpool:https://api.openweathermap.org:443 "GET /data/2.5/weather?q=Shelekhov&appid=da8eff3043fc441cca70712be72d110b&units=metric HTTP/1.1" 200 517
DEBUG:urllib3.connectionpool:Starting new HTTPS connection (1): api.openweathermap.org:443
DEBUG:urllib3.connectionpool:https://api.openweathermap.org:443 "GET /data/2.5/weather?q=Shelekhov&appid=da8eff3043fc441cca70712be72d110b&units=metric HTTP/1.1" 200 517
INFO:django.utils.autoreload:/Users/ivansizov/Documents/work/WeatherProject/WeatherProject/src/wardrobe/services/outfit_generation_logic.py changed, reloading.
DEBUG:urllib3.connectionpool:Starting new HTTPS connection (1): api.openweathermap.org:443
DEBUG:urllib3.connectionpool:https://api.openweathermap.org:443 "GET /data/2.5/weather?q=Shelekhov&appid=da8eff3043fc441cca70712be72d110b&units=metric HTTP/1.1" 200 517
INFO:django.utils.autoreload:/Users/ivansizov/Documents/work/WeatherProject/WeatherProject/src/wardrobe/services/outfit_generation_logic.py changed, reloading.
DEBUG:urllib3.connectionpool:Starting new HTTPS connection (1): api.openweathermap.org:443
DEBUG:urllib3.connectionpool:https://api.openweathermap.org:443 "GET /data/2.5/weather?q=Shelekhov&appid=da8eff3043fc441cca70712be72d110b&units=metric HTTP/1.1" 200 517
DEBUG:urllib3.connectionpool:Starting new HTTPS connection (1): api.openweathermap.org:443
DEBUG:urllib3.connectionpool:https://api.openweathermap.org:443 "GET /data/2.5/weather?q=Shelekhov&appid=da8eff3043fc441cca70712be72d110b&units=metric HTTP/1.1" 200 517
WARNING:django.request:Not Found: /accounts/login/
DEBUG:urllib3.connectionpool:Starting new HTTPS connection (1): api.openweathermap.org:443
DEBUG:urllib3.connectionpool:https://api.openweathermap.org:443 "GET /data/2.5/weather?q=Baltiysk&appid=da8eff3043fc441cca70712be72d110b&units=metric HTTP/1.1" 200 521
DEBUG:urllib3.connectionpool:Starting new HTTPS connection (1): api.openweathermap.org:443
DEBUG:urllib3.connectionpool:https://api.openweathermap.org:443 "GET /data/2.5/weather?q=Baltiysk&appid=da8eff3043fc441cca70712be72d110b&units=metric HTTP/1.1" 200 521
DEBUG:urllib3.connectionpool:Starting new HTTPS connection (1): api.openweathermap.org:443
DEBUG:urllib3.connectionpool:https://api.openweathermap.org:443 "GET /data/2.5/weather?q=Baltiysk&appid=da8eff3043fc441cca70712be72d110b&units=metric HTTP/1.1" 200 521
DEBUG:urllib3.connectionpool:Starting new HTTPS connection (1): api.openweathermap.org:443
DEBUG:urllib3.connectionpool:https://api.openweathermap.org:443 "GET /data/2.5/weather?q=Baltiysk&appid=da8eff3043fc441cca70712be72d110b&units=metric HTTP/1.1" 200 521
WARNING:django.request:Not Found: /
WARNING:django.request:Not Found: /favicon.ico
WARNING:django.request:Not Found: /accounts/login/
WARNING:django.request:Not Found: /accounts/login/
DEBUG:urllib3.connectionpool:Starting new HTTPS connection (1): api.openweathermap.org:443
DEBUG:urllib3.connectionpool:https://api.openweathermap.org:443 "GET /data/2.5/weather?q=Baltiysk&appid=da8eff3043fc441cca70712be72d110b&units=metric HTTP/1.1" 200 522
DEBUG:urllib3.connectionpool:Starting new HTTPS connection (1): api.openweathermap.org:443
DEBUG:urllib3.connectionpool:https://api.openweathermap.org:443 "GET /data/2.5/weather?q=Krasnoyarsk&appid=da8eff3043fc441cca70712be72d110b&units=metric HTTP/1.1" 200 523
DEBUG:urllib3.connectionpool:Starting new HTTPS connection (1): api.openweathermap.org:443
DEBUG:urllib3.connectionpool:https://api.openweathermap.org:443 "GET /data/2.5/weather?q=Krasnoyarsk&appid=da8eff3043fc441cca70712be72d110b&units=metric HTTP/1.1" 200 523
DEBUG:urllib3.connectionpool:Starting new HTTPS connection (1): api.openweathermap.org:443
DEBUG:urllib3.connectionpool:https://api.openweathermap.org:443 "GET /data/2.5/weather?q=Krasnoyarsk&appid=da8eff3043fc441cca70712be72d110b&units=metric HTTP/1.1" 200 523
DEBUG:urllib3.connectionpool:Starting new HTTPS connection (1): api.openweathermap.org:443
DEBUG:urllib3.connectionpool:https://api.openweathermap.org:443 "GET /data/2.5/weather?q=Krasnoyarsk&appid=da8eff3043fc441cca70712be72d110b&units=metric HTTP/1.1" 200 523
DEBUG:urllib3.connectionpool:Starting new HTTPS connection (1): api.openweathermap.org:443
DEBUG:urllib3.connectionpool:https://api.openweathermap.org:443 "GET /data/2.5/weather?q=Krasnoyarsk&appid=da8eff3043fc441cca70712be72d110b&units=metric HTTP/1.1" 200 523
DEBUG:urllib3.connectionpool:Starting new HTTPS connection (1): api.openweathermap.org:443
DEBUG:urllib3.connectionpool:https://api.openweathermap.org:443 "GET /data/2.5/weather?q=Krasnoyarsk&appid=da8eff3043fc441cca70712be72d110b&units=metric HTTP/1.1" 200 523
DEBUG:urllib3.connectionpool:Starting new HTTPS connection (1): api.openweathermap.org:443
DEBUG:urllib3.connectionpool:https://api.openweathermap.org:443 "GET /data/2.5/weather?q=Krasnoyarsk&appid=da8eff3043fc441cca70712be72d110b&units=metric HTTP/1.1" 200 523
DEBUG:urllib3.connectionpool:Starting new HTTPS connection (1): api.openweathermap.org:443
DEBUG:urllib3.connectionpool:https://api.openweathermap.org:443 "GET /data/2.5/weather?q=Krasnoyarsk&appid=da8eff3043fc441cca70712be72d110b&units=metric HTTP/1.1" 200 523
DEBUG:urllib3.connectionpool:Starting new HTTPS connection (1): api.openweathermap.org:443
DEBUG:urllib3.connectionpool:https://api.openweathermap.org:443 "GET /data/2.5/weather?q=Krasnoyarsk&appid=da8eff3043fc441cca70712be72d110b&units=metric HTTP/1.1" 200 523
DEBUG:urllib3.connectionpool:Starting new HTTPS connection (1): api.openweathermap.org:443
DEBUG:urllib3.connectionpool:https://api.openweathermap.org:443 "GET /data/2.5/weather?q=Krasnoyarsk&appid=da8eff3043fc441cca70712be72d110b&units=metric HTTP/1.1" 200 523
DEBUG:urllib3.connectionpool:Starting new HTTPS connection (1): api.openweathermap.org:443
DEBUG:urllib3.connectionpool:https://api.openweathermap.org:443 "GET /data/2.5/weather?q=Krasnoyarsk&appid=da8eff3043fc441cca70712be72d110b&units=metric HTTP/1.1" 200 523
DEBUG:urllib3.connectionpool:Starting new HTTPS connection (1): api.openweathermap.org:443
DEBUG:urllib3.connectionpool:https://api.openweathermap.org:443 "GET /data/2.5/weather?q=Krasnoyarsk&appid=da8eff3043fc441cca70712be72d110b&units=metric HTTP/1.1" 200 523
DEBUG:urllib3.connectionpool:Starting new HTTPS connection (1): api.openweathermap.org:443
DEBUG:urllib3.connectionpool:https://api.openweathermap.org:443 "GET /data/2.5/weather?q=Krasnoyarsk&appid=da8eff3043fc441cca70712be72d110b&units=metric HTTP/1.1" 200 523
DEBUG:urllib3.connectionpool:Starting new HTTPS connection (1): api.openweathermap.org:443
DEBUG:urllib3.connectionpool:https://api.openweathermap.org:443 "GET /data/2.5/weather?q=Krasnoyarsk&appid=da8eff3043fc441cca70712be72d110b&units=metric HTTP/1.1" 200 523
DEBUG:urllib3.connectionpool:Starting new HTTPS connection (1): api.openweathermap.org:443
DEBUG:urllib3.connectionpool:https://api.openweathermap.org:443 "GET /data/2.5/weather?q=Krasnoyarsk&appid=da8eff3043fc441cca70712be72d110b&units=metric HTTP/1.1" 200 523
DEBUG:urllib3.connectionpool:Starting new HTTPS connection (1): api.openweathermap.org:443
DEBUG:urllib3.connectionpool:https://api.openweathermap.org:443 "GET /data/2.5/weather?q=Krasnoyarsk&appid=da8eff3043fc441cca70712be72d110b&units=metric HTTP/1.1" 200 523
DEBUG:urllib3.connectionpool:Starting new HTTPS connection (1): api.openweathermap.org:443
DEBUG:urllib3.connectionpool:https://api.openweathermap.org:443 "GET /data/2.5/weather?q=Krasnoyarsk&appid=da8eff3043fc441cca70712be72d110b&units=metric HTTP/1.1" 200 523
DEBUG:urllib3.connectionpool:Starting new HTTPS connection (1): api.openweathermap.org:443
DEBUG:urllib3.connectionpool:https://api.openweathermap.org:443 "GET /data/2.5/weather?q=Krasnoyarsk&appid=da8eff3043fc441cca70712be72d110b&units=metric HTTP/1.1" 200 523
DEBUG:urllib3.connectionpool:Starting new HTTPS connection (1): api.openweathermap.org:443
DEBUG:urllib3.connectionpool:https://api.openweathermap.org:443 "GET /data/2.5/weather?q=Krasnoyarsk&appid=da8eff3043fc441cca70712be72d110b&units=metric HTTP/1.1" 200 523
DEBUG:urllib3.connectionpool:Starting new HTTPS connection (1): api.openweathermap.org:443
DEBUG:urllib3.connectionpool:https://api.openweathermap.org:443 "GET /data/2.5/weather?q=Krasnoyarsk&appid=da8eff3043fc441cca70712be72d110b&units=metric HTTP/1.1" 200 523
DEBUG:urllib3.connectionpool:Starting new HTTPS connection (1): api.openweathermap.org:443
DEBUG:urllib3.connectionpool:https://api.openweathermap.org:443 "GET /data/2.5/weather?q=Krasnoyarsk&appid=da8eff3043fc441cca70712be72d110b&units=metric HTTP/1.1" 200 523
DEBUG:urllib3.connectionpool:Starting new HTTPS connection (1): api.openweathermap.org:443
DEBUG:urllib3.connectionpool:https://api.openweathermap.org:443 "GET /data/2.5/weather?q=Krasnoyarsk&appid=da8eff3043fc441cca70712be72d110b&units=metric HTTP/1.1" 200 523
INFO:django.utils.autoreload:C:\Users\Иван\PycharmProjects\WeatherProject\Wardrobe-Weather-Project\WeatherProject\src\wardrobe\views.py changed, reloading.
INFO:django.utils.autoreload:C:\Users\Иван\PycharmProjects\WeatherProject\Wardrobe-Weather-Project\WeatherProject\src\wardrobe\views.py changed, reloading.
INFO:django.utils.autoreload:C:\Users\Иван\PycharmProjects\WeatherProject\Wardrobe-Weather-Project\WeatherProject\src\wardrobe\urls.py changed, reloading.
INFO:django.utils.autoreload:C:\Users\Иван\PycharmProjects\WeatherProject\Wardrobe-Weather-Project\WeatherProject\src\wardrobe\urls.py changed, reloading.
WARNING:django.request:Not Found: /
DEBUG:urllib3.connectionpool:Starting new HTTPS connection (1): api.openweathermap.org:443
DEBUG:urllib3.connectionpool:https://api.openweathermap.org:443 "GET /data/2.5/weather?q=Krasnoyarsk&appid=da8eff3043fc441cca70712be72d110b&units=metric HTTP/1.1" 200 522
DEBUG:urllib3.connectionpool:Starting new HTTPS connection (1): api.openweathermap.org:443
DEBUG:urllib3.connectionpool:https://api.openweathermap.org:443 "GET /data/2.5/weather?q=Krasnoyarsk&appid=da8eff3043fc441cca70712be72d110b&units=metric HTTP/1.1" 200 522
DEBUG:urllib3.connectionpool:Starting new HTTPS connection (1): api.openweathermap.org:443
DEBUG:urllib3.connectionpool:https://api.openweathermap.org:443 "GET /data/2.5/weather?q=Krasnoyarsk&appid=da8eff3043fc441cca70712be72d110b&units=metric HTTP/1.1" 200 522
DEBUG:urllib3.connectionpool:Starting new HTTPS connection (1): api.openweathermap.org:443
DEBUG:urllib3.connectionpool:https://api.openweathermap.org:443 "GET /data/2.5/weather?q=Krasnoyarsk&appid=da8eff3043fc441cca70712be72d110b&units=metric HTTP/1.1" 200 522
DEBUG:urllib3.connectionpool:Starting new HTTPS connection (1): api.openweathermap.org:443
DEBUG:urllib3.connectionpool:https://api.openweathermap.org:443 "GET /data/2.5/weather?q=Krasnoyarsk&appid=da8eff3043fc441cca70712be72d110b&units=metric HTTP/1.1" 200 522
ERROR:django.request:Internal Server Error: /wardrobe/delete
Traceback (most recent call last):
  File "C:\Users\Иван\PycharmProjects\WeatherProject\Wardrobe-Weather-Project\WeatherProject\src\wardrobe\services\clothes_CRUD_operations.py", line 30, in delete_clothes_logic
    item = Clothes.objects.get(pk=item_id)
  File "C:\Users\Иван\AppData\Local\Programs\Python\Python38\lib\site-packages\django\db\models\manager.py", line 85, in manager_method
    return getattr(self.get_queryset(), name)(*args, **kwargs)
  File "C:\Users\Иван\AppData\Local\Programs\Python\Python38\lib\site-packages\django\db\models\query.py", line 650, in get
    raise self.model.DoesNotExist(
src.wardrobe.models.Clothes.DoesNotExist: Clothes matching query does not exist.

During handling of the above exception, another exception occurred:

Traceback (most recent call last):
  File "C:\Users\Иван\AppData\Local\Programs\Python\Python38\lib\site-packages\django\core\handlers\exception.py", line 55, in inner
    response = get_response(request)
  File "C:\Users\Иван\AppData\Local\Programs\Python\Python38\lib\site-packages\django\core\handlers\base.py", line 197, in _get_response
    response = wrapped_callback(request, *callback_args, **callback_kwargs)
  File "C:\Users\Иван\PycharmProjects\WeatherProject\Wardrobe-Weather-Project\WeatherProject\src\wardrobe\views.py", line 48, in delete_clothes_view
    delete_clothes_logic(request)
  File "C:\Users\Иван\PycharmProjects\WeatherProject\Wardrobe-Weather-Project\WeatherProject\src\wardrobe\services\clothes_CRUD_operations.py", line 33, in delete_clothes_logic
    except Clothes.objects.DoesNotExist:
AttributeError: 'Manager' object has no attribute 'DoesNotExist'
INFO:django.utils.autoreload:C:\Users\Иван\PycharmProjects\WeatherProject\Wardrobe-Weather-Project\WeatherProject\src\wardrobe\services\clothes_CRUD_operations.py changed, reloading.
DEBUG:urllib3.connectionpool:Starting new HTTPS connection (1): api.openweathermap.org:443
DEBUG:urllib3.connectionpool:https://api.openweathermap.org:443 "GET /data/2.5/weather?q=Krasnoyarsk&appid=da8eff3043fc441cca70712be72d110b&units=metric HTTP/1.1" 200 522
INFO:django.utils.autoreload:C:\Users\Иван\PycharmProjects\WeatherProject\Wardrobe-Weather-Project\WeatherProject\src\wardrobe\services\clothes_CRUD_operations.py changed, reloading.
DEBUG:urllib3.connectionpool:Starting new HTTPS connection (1): api.openweathermap.org:443
DEBUG:urllib3.connectionpool:https://api.openweathermap.org:443 "GET /data/2.5/weather?q=Krasnoyarsk&appid=da8eff3043fc441cca70712be72d110b&units=metric HTTP/1.1" 200 522
DEBUG:urllib3.connectionpool:Starting new HTTPS connection (1): api.openweathermap.org:443
DEBUG:urllib3.connectionpool:https://api.openweathermap.org:443 "GET /data/2.5/weather?q=Krasnoyarsk&appid=da8eff3043fc441cca70712be72d110b&units=metric HTTP/1.1" 200 522
INFO:django.utils.autoreload:C:\Users\Иван\PycharmProjects\WeatherProject\Wardrobe-Weather-Project\WeatherProject\src\wardrobe\views.py changed, reloading.
DEBUG:urllib3.connectionpool:Starting new HTTPS connection (1): api.openweathermap.org:443
DEBUG:urllib3.connectionpool:https://api.openweathermap.org:443 "GET /data/2.5/weather?q=Krasnoyarsk&appid=da8eff3043fc441cca70712be72d110b&units=metric HTTP/1.1" 200 522
INFO:django.utils.autoreload:C:\Users\Иван\PycharmProjects\WeatherProject\Wardrobe-Weather-Project\WeatherProject\src\wardrobe\views.py changed, reloading.
DEBUG:urllib3.connectionpool:Starting new HTTPS connection (1): api.openweathermap.org:443
DEBUG:urllib3.connectionpool:https://api.openweathermap.org:443 "GET /data/2.5/weather?q=Krasnoyarsk&appid=da8eff3043fc441cca70712be72d110b&units=metric HTTP/1.1" 200 522
INFO:django.utils.autoreload:C:\Users\Иван\PycharmProjects\WeatherProject\Wardrobe-Weather-Project\WeatherProject\src\wardrobe\services\clothes_CRUD_operations.py changed, reloading.
DEBUG:urllib3.connectionpool:Starting new HTTPS connection (1): api.openweathermap.org:443
DEBUG:urllib3.connectionpool:https://api.openweathermap.org:443 "GET /data/2.5/weather?q=Krasnoyarsk&appid=da8eff3043fc441cca70712be72d110b&units=metric HTTP/1.1" 200 522
DEBUG:urllib3.connectionpool:Starting new HTTPS connection (1): api.openweathermap.org:443
DEBUG:urllib3.connectionpool:https://api.openweathermap.org:443 "GET /data/2.5/weather?q=Krasnoyarsk&appid=da8eff3043fc441cca70712be72d110b&units=metric HTTP/1.1" 200 522
DEBUG:urllib3.connectionpool:Starting new HTTPS connection (1): api.openweathermap.org:443
DEBUG:urllib3.connectionpool:https://api.openweathermap.org:443 "GET /data/2.5/weather?q=Krasnoyarsk&appid=da8eff3043fc441cca70712be72d110b&units=metric HTTP/1.1" 200 522
DEBUG:urllib3.connectionpool:Starting new HTTPS connection (1): api.openweathermap.org:443
DEBUG:urllib3.connectionpool:https://api.openweathermap.org:443 "GET /data/2.5/weather?q=Krasnoyarsk&appid=da8eff3043fc441cca70712be72d110b&units=metric HTTP/1.1" 200 522
DEBUG:urllib3.connectionpool:Starting new HTTPS connection (1): api.openweathermap.org:443
DEBUG:urllib3.connectionpool:https://api.openweathermap.org:443 "GET /data/2.5/weather?q=Krasnoyarsk&appid=da8eff3043fc441cca70712be72d110b&units=metric HTTP/1.1" 200 522
DEBUG:urllib3.connectionpool:Starting new HTTPS connection (1): api.openweathermap.org:443
DEBUG:urllib3.connectionpool:https://api.openweathermap.org:443 "GET /data/2.5/weather?q=Krasnoyarsk&appid=da8eff3043fc441cca70712be72d110b&units=metric HTTP/1.1" 200 522
DEBUG:urllib3.connectionpool:Starting new HTTPS connection (1): api.openweathermap.org:443
DEBUG:urllib3.connectionpool:https://api.openweathermap.org:443 "GET /data/2.5/weather?q=Krasnoyarsk&appid=da8eff3043fc441cca70712be72d110b&units=metric HTTP/1.1" 200 522
DEBUG:urllib3.connectionpool:Starting new HTTPS connection (1): api.openweathermap.org:443
DEBUG:urllib3.connectionpool:https://api.openweathermap.org:443 "GET /data/2.5/weather?q=Krasnoyarsk&appid=da8eff3043fc441cca70712be72d110b&units=metric HTTP/1.1" 200 522
DEBUG:urllib3.connectionpool:Starting new HTTPS connection (1): api.openweathermap.org:443
DEBUG:urllib3.connectionpool:https://api.openweathermap.org:443 "GET /data/2.5/weather?q=Krasnoyarsk&appid=da8eff3043fc441cca70712be72d110b&units=metric HTTP/1.1" 200 522
DEBUG:urllib3.connectionpool:Starting new HTTPS connection (1): api.openweathermap.org:443
DEBUG:urllib3.connectionpool:https://api.openweathermap.org:443 "GET /data/2.5/weather?q=Krasnoyarsk&appid=da8eff3043fc441cca70712be72d110b&units=metric HTTP/1.1" 200 522
DEBUG:urllib3.connectionpool:Starting new HTTPS connection (1): api.openweathermap.org:443
DEBUG:urllib3.connectionpool:https://api.openweathermap.org:443 "GET /data/2.5/weather?q=Krasnoyarsk&appid=da8eff3043fc441cca70712be72d110b&units=metric HTTP/1.1" 200 522
DEBUG:urllib3.connectionpool:Starting new HTTPS connection (1): api.openweathermap.org:443
DEBUG:urllib3.connectionpool:https://api.openweathermap.org:443 "GET /data/2.5/weather?q=Krasnoyarsk&appid=da8eff3043fc441cca70712be72d110b&units=metric HTTP/1.1" 200 522
DEBUG:urllib3.connectionpool:Starting new HTTPS connection (1): api.openweathermap.org:443
DEBUG:urllib3.connectionpool:https://api.openweathermap.org:443 "GET /data/2.5/weather?q=Krasnoyarsk&appid=da8eff3043fc441cca70712be72d110b&units=metric HTTP/1.1" 200 522
DEBUG:urllib3.connectionpool:Starting new HTTPS connection (1): api.openweathermap.org:443
DEBUG:urllib3.connectionpool:https://api.openweathermap.org:443 "GET /data/2.5/weather?q=Krasnoyarsk&appid=da8eff3043fc441cca70712be72d110b&units=metric HTTP/1.1" 200 522
DEBUG:urllib3.connectionpool:Starting new HTTPS connection (1): api.openweathermap.org:443
DEBUG:urllib3.connectionpool:https://api.openweathermap.org:443 "GET /data/2.5/weather?q=Krasnoyarsk&appid=da8eff3043fc441cca70712be72d110b&units=metric HTTP/1.1" 200 522
DEBUG:urllib3.connectionpool:Starting new HTTPS connection (1): api.openweathermap.org:443
DEBUG:urllib3.connectionpool:https://api.openweathermap.org:443 "GET /data/2.5/weather?q=Krasnoyarsk&appid=da8eff3043fc441cca70712be72d110b&units=metric HTTP/1.1" 200 522
INFO:django.utils.autoreload:C:\Users\Иван\PycharmProjects\WeatherProject\Wardrobe-Weather-Project\WeatherProject\src\wardrobe\views.py changed, reloading.
DEBUG:urllib3.connectionpool:Starting new HTTPS connection (1): api.openweathermap.org:443
DEBUG:urllib3.connectionpool:https://api.openweathermap.org:443 "GET /data/2.5/weather?q=Krasnoyarsk&appid=da8eff3043fc441cca70712be72d110b&units=metric HTTP/1.1" 200 522
ERROR:django.request:Internal Server Error: /wardrobe/delete
Traceback (most recent call last):
  File "C:\Users\Иван\AppData\Local\Programs\Python\Python38\lib\site-packages\django\core\handlers\exception.py", line 55, in inner
    response = get_response(request)
  File "C:\Users\Иван\AppData\Local\Programs\Python\Python38\lib\site-packages\django\core\handlers\base.py", line 204, in _get_response
    self.check_response(response, callback)
  File "C:\Users\Иван\AppData\Local\Programs\Python\Python38\lib\site-packages\django\core\handlers\base.py", line 332, in check_response
    raise ValueError(
ValueError: The view src.wardrobe.views.delete_clothes_view didn't return an HttpResponse object. It returned None instead.
DEBUG:urllib3.connectionpool:Starting new HTTPS connection (1): api.openweathermap.org:443
DEBUG:urllib3.connectionpool:https://api.openweathermap.org:443 "GET /data/2.5/weather?q=Krasnoyarsk&appid=da8eff3043fc441cca70712be72d110b&units=metric HTTP/1.1" 200 522
INFO:django.utils.autoreload:C:\Users\Иван\PycharmProjects\WeatherProject\Wardrobe-Weather-Project\WeatherProject\src\wardrobe\views.py changed, reloading.
DEBUG:urllib3.connectionpool:Starting new HTTPS connection (1): api.openweathermap.org:443
DEBUG:urllib3.connectionpool:https://api.openweathermap.org:443 "GET /data/2.5/weather?q=Krasnoyarsk&appid=da8eff3043fc441cca70712be72d110b&units=metric HTTP/1.1" 200 522
DEBUG:urllib3.connectionpool:Starting new HTTPS connection (1): api.openweathermap.org:443
DEBUG:urllib3.connectionpool:https://api.openweathermap.org:443 "GET /data/2.5/weather?q=Krasnoyarsk&appid=da8eff3043fc441cca70712be72d110b&units=metric HTTP/1.1" 200 522
DEBUG:urllib3.connectionpool:Starting new HTTPS connection (1): api.openweathermap.org:443
DEBUG:urllib3.connectionpool:https://api.openweathermap.org:443 "GET /data/2.5/weather?q=Krasnoyarsk&appid=da8eff3043fc441cca70712be72d110b&units=metric HTTP/1.1" 200 522
WARNING:django.security.csrf:Forbidden (CSRF token missing.): /wardrobe/delete
WARNING:django.security.csrf:Forbidden (CSRF token missing.): /wardrobe/delete
DEBUG:urllib3.connectionpool:Starting new HTTPS connection (1): api.openweathermap.org:443
DEBUG:urllib3.connectionpool:https://api.openweathermap.org:443 "GET /data/2.5/weather?q=Krasnoyarsk&appid=da8eff3043fc441cca70712be72d110b&units=metric HTTP/1.1" 200 522
DEBUG:urllib3.connectionpool:Starting new HTTPS connection (1): api.openweathermap.org:443
DEBUG:urllib3.connectionpool:https://api.openweathermap.org:443 "GET /data/2.5/weather?q=Krasnoyarsk&appid=da8eff3043fc441cca70712be72d110b&units=metric HTTP/1.1" 200 522
WARNING:django.security.csrf:Forbidden (CSRF token missing.): /wardrobe/delete
WARNING:django.security.csrf:Forbidden (CSRF token missing.): /wardrobe/delete
DEBUG:urllib3.connectionpool:Starting new HTTPS connection (1): api.openweathermap.org:443
DEBUG:urllib3.connectionpool:https://api.openweathermap.org:443 "GET /data/2.5/weather?q=Krasnoyarsk&appid=da8eff3043fc441cca70712be72d110b&units=metric HTTP/1.1" 200 522
WARNING:django.security.csrf:Forbidden (CSRF token missing.): /wardrobe/delete
WARNING:django.security.csrf:Forbidden (CSRF token missing.): /wardrobe/delete
DEBUG:urllib3.connectionpool:Starting new HTTPS connection (1): api.openweathermap.org:443
DEBUG:urllib3.connectionpool:https://api.openweathermap.org:443 "GET /data/2.5/weather?q=Krasnoyarsk&appid=da8eff3043fc441cca70712be72d110b&units=metric HTTP/1.1" 200 522
DEBUG:urllib3.connectionpool:Starting new HTTPS connection (1): api.openweathermap.org:443
DEBUG:urllib3.connectionpool:https://api.openweathermap.org:443 "GET /data/2.5/weather?q=Krasnoyarsk&appid=da8eff3043fc441cca70712be72d110b&units=metric HTTP/1.1" 200 522
WARNING:django.security.csrf:Forbidden (CSRF token missing.): /wardrobe/delete
WARNING:django.security.csrf:Forbidden (CSRF token missing.): /wardrobe/delete
DEBUG:urllib3.connectionpool:Starting new HTTPS connection (1): api.openweathermap.org:443
DEBUG:urllib3.connectionpool:https://api.openweathermap.org:443 "GET /data/2.5/weather?q=Krasnoyarsk&appid=da8eff3043fc441cca70712be72d110b&units=metric HTTP/1.1" 200 522
INFO:django.utils.autoreload:C:\Users\Иван\PycharmProjects\WeatherProject\Wardrobe-Weather-Project\WeatherProject\src\wardrobe\services\clothes_CRUD_operations.py changed, reloading.
WARNING:django.security.csrf:Forbidden (CSRF token missing.): /wardrobe/delete
WARNING:django.security.csrf:Forbidden (CSRF token missing.): /wardrobe/delete
DEBUG:urllib3.connectionpool:Starting new HTTPS connection (1): api.openweathermap.org:443
DEBUG:urllib3.connectionpool:https://api.openweathermap.org:443 "GET /data/2.5/weather?q=Krasnoyarsk&appid=da8eff3043fc441cca70712be72d110b&units=metric HTTP/1.1" 200 522
DEBUG:urllib3.connectionpool:Starting new HTTPS connection (1): api.openweathermap.org:443
DEBUG:urllib3.connectionpool:https://api.openweathermap.org:443 "GET /data/2.5/weather?q=Krasnoyarsk&appid=da8eff3043fc441cca70712be72d110b&units=metric HTTP/1.1" 200 523
WARNING:django.security.csrf:Forbidden (CSRF token missing.): /wardrobe/delete
WARNING:django.security.csrf:Forbidden (CSRF token missing.): /wardrobe/delete
DEBUG:urllib3.connectionpool:Starting new HTTPS connection (1): api.openweathermap.org:443
DEBUG:urllib3.connectionpool:https://api.openweathermap.org:443 "GET /data/2.5/weather?q=Krasnoyarsk&appid=da8eff3043fc441cca70712be72d110b&units=metric HTTP/1.1" 200 523
WARNING:django.security.csrf:Forbidden (CSRF token missing.): /wardrobe/delete
DEBUG:urllib3.connectionpool:Starting new HTTPS connection (1): api.openweathermap.org:443
DEBUG:urllib3.connectionpool:https://api.openweathermap.org:443 "GET /data/2.5/weather?q=Krasnoyarsk&appid=da8eff3043fc441cca70712be72d110b&units=metric HTTP/1.1" 200 523
WARNING:django.security.csrf:Forbidden (CSRF token missing.): /wardrobe/delete
DEBUG:urllib3.connectionpool:Starting new HTTPS connection (1): api.openweathermap.org:443
DEBUG:urllib3.connectionpool:https://api.openweathermap.org:443 "GET /data/2.5/weather?q=Krasnoyarsk&appid=da8eff3043fc441cca70712be72d110b&units=metric HTTP/1.1" 200 523
WARNING:django.security.csrf:Forbidden (CSRF token missing.): /wardrobe/delete
INFO:django.utils.autoreload:C:\Users\Иван\PycharmProjects\WeatherProject\Wardrobe-Weather-Project\WeatherProject\src\wardrobe\services\clothes_CRUD_operations.py changed, reloading.
DEBUG:urllib3.connectionpool:Starting new HTTPS connection (1): api.openweathermap.org:443
DEBUG:urllib3.connectionpool:https://api.openweathermap.org:443 "GET /data/2.5/weather?q=Krasnoyarsk&appid=da8eff3043fc441cca70712be72d110b&units=metric HTTP/1.1" 200 523
WARNING:django.security.csrf:Forbidden (CSRF token missing.): /wardrobe/delete
DEBUG:urllib3.connectionpool:Starting new HTTPS connection (1): api.openweathermap.org:443
DEBUG:urllib3.connectionpool:https://api.openweathermap.org:443 "GET /data/2.5/weather?q=Krasnoyarsk&appid=da8eff3043fc441cca70712be72d110b&units=metric HTTP/1.1" 200 523
WARNING:django.security.csrf:Forbidden (CSRF token missing.): /wardrobe/delete
WARNING:django.security.csrf:Forbidden (CSRF token missing.): /wardrobe/delete
WARNING:django.security.csrf:Forbidden (CSRF token missing.): /wardrobe/delete
WARNING:django.security.csrf:Forbidden (CSRF token missing.): /wardrobe/delete
DEBUG:urllib3.connectionpool:Starting new HTTPS connection (1): api.openweathermap.org:443
DEBUG:urllib3.connectionpool:https://api.openweathermap.org:443 "GET /data/2.5/weather?q=Krasnoyarsk&appid=da8eff3043fc441cca70712be72d110b&units=metric HTTP/1.1" 200 523
INFO:django.utils.autoreload:C:\Users\Иван\PycharmProjects\WeatherProject\Wardrobe-Weather-Project\WeatherProject\src\wardrobe\services\clothes_CRUD_operations.py changed, reloading.
DEBUG:urllib3.connectionpool:Starting new HTTPS connection (1): api.openweathermap.org:443
DEBUG:urllib3.connectionpool:https://api.openweathermap.org:443 "GET /data/2.5/weather?q=Krasnoyarsk&appid=da8eff3043fc441cca70712be72d110b&units=metric HTTP/1.1" 200 523
DEBUG:urllib3.connectionpool:Starting new HTTPS connection (1): api.openweathermap.org:443
DEBUG:urllib3.connectionpool:https://api.openweathermap.org:443 "GET /data/2.5/weather?q=Krasnoyarsk&appid=da8eff3043fc441cca70712be72d110b&units=metric HTTP/1.1" 200 523
ERROR:django.request:Internal Server Error: /profile/
Traceback (most recent call last):
  File "C:\Users\Иван\AppData\Local\Programs\Python\Python38\lib\site-packages\django\core\handlers\exception.py", line 55, in inner
    response = get_response(request)
  File "C:\Users\Иван\AppData\Local\Programs\Python\Python38\lib\site-packages\django\core\handlers\base.py", line 197, in _get_response
    response = wrapped_callback(request, *callback_args, **callback_kwargs)
  File "C:\Users\Иван\AppData\Local\Programs\Python\Python38\lib\site-packages\django\contrib\auth\decorators.py", line 23, in _wrapped_view
    return view_func(request, *args, **kwargs)
  File "C:\Users\Иван\PycharmProjects\WeatherProject\Wardrobe-Weather-Project\WeatherProject\src\client\views.py", line 32, in profile
    return render(request, 'user/profile.html', context)
  File "C:\Users\Иван\AppData\Local\Programs\Python\Python38\lib\site-packages\django\shortcuts.py", line 24, in render
    content = loader.render_to_string(template_name, context, request, using=using)
  File "C:\Users\Иван\AppData\Local\Programs\Python\Python38\lib\site-packages\django\template\loader.py", line 62, in render_to_string
    return template.render(context, request)
  File "C:\Users\Иван\AppData\Local\Programs\Python\Python38\lib\site-packages\django\template\backends\django.py", line 62, in render
    return self.template.render(context)
  File "C:\Users\Иван\AppData\Local\Programs\Python\Python38\lib\site-packages\django\template\base.py", line 175, in render
    return self._render(context)
  File "C:\Users\Иван\AppData\Local\Programs\Python\Python38\lib\site-packages\django\test\utils.py", line 111, in instrumented_test_render
    return self.nodelist.render(context)
  File "C:\Users\Иван\AppData\Local\Programs\Python\Python38\lib\site-packages\django\template\base.py", line 1005, in render
    return SafeString("".join([node.render_annotated(context) for node in self]))
  File "C:\Users\Иван\AppData\Local\Programs\Python\Python38\lib\site-packages\django\template\base.py", line 1005, in <listcomp>
    return SafeString("".join([node.render_annotated(context) for node in self]))
  File "C:\Users\Иван\AppData\Local\Programs\Python\Python38\lib\site-packages\django\template\base.py", line 966, in render_annotated
    return self.render(context)
  File "C:\Users\Иван\AppData\Local\Programs\Python\Python38\lib\site-packages\django\template\defaulttags.py", line 238, in render
    nodelist.append(node.render_annotated(context))
  File "C:\Users\Иван\AppData\Local\Programs\Python\Python38\lib\site-packages\django\template\base.py", line 966, in render_annotated
    return self.render(context)
  File "C:\Users\Иван\AppData\Local\Programs\Python\Python38\lib\site-packages\django\template\defaulttags.py", line 238, in render
    nodelist.append(node.render_annotated(context))
  File "C:\Users\Иван\AppData\Local\Programs\Python\Python38\lib\site-packages\django\template\base.py", line 966, in render_annotated
    return self.render(context)
  File "C:\Users\Иван\AppData\Local\Programs\Python\Python38\lib\site-packages\django\template\defaulttags.py", line 472, in render
    url = reverse(view_name, args=args, kwargs=kwargs, current_app=current_app)
  File "C:\Users\Иван\AppData\Local\Programs\Python\Python38\lib\site-packages\django\urls\base.py", line 88, in reverse
    return resolver._reverse_with_prefix(view, prefix, *args, **kwargs)
  File "C:\Users\Иван\AppData\Local\Programs\Python\Python38\lib\site-packages\django\urls\resolvers.py", line 828, in _reverse_with_prefix
    raise NoReverseMatch(msg)
django.urls.exceptions.NoReverseMatch: Reverse for 'delete_lothes_view' not found. 'delete_lothes_view' is not a valid view function or pattern name.
DEBUG:urllib3.connectionpool:Starting new HTTPS connection (1): api.openweathermap.org:443
DEBUG:urllib3.connectionpool:https://api.openweathermap.org:443 "GET /data/2.5/weather?q=Krasnoyarsk&appid=da8eff3043fc441cca70712be72d110b&units=metric HTTP/1.1" 200 523
DEBUG:urllib3.connectionpool:Starting new HTTPS connection (1): api.openweathermap.org:443
DEBUG:urllib3.connectionpool:https://api.openweathermap.org:443 "GET /data/2.5/weather?q=Krasnoyarsk&appid=da8eff3043fc441cca70712be72d110b&units=metric HTTP/1.1" 200 523
DEBUG:urllib3.connectionpool:Starting new HTTPS connection (1): api.openweathermap.org:443
DEBUG:urllib3.connectionpool:https://api.openweathermap.org:443 "GET /data/2.5/weather?q=Krasnoyarsk&appid=da8eff3043fc441cca70712be72d110b&units=metric HTTP/1.1" 200 523
DEBUG:urllib3.connectionpool:Starting new HTTPS connection (1): api.openweathermap.org:443
DEBUG:urllib3.connectionpool:https://api.openweathermap.org:443 "GET /data/2.5/weather?q=Krasnoyarsk&appid=da8eff3043fc441cca70712be72d110b&units=metric HTTP/1.1" 200 523
INFO:django.utils.autoreload:C:\Users\Иван\PycharmProjects\WeatherProject\Wardrobe-Weather-Project\WeatherProject\src\wardrobe\services\clothes_CRUD_operations.py changed, reloading.
DEBUG:urllib3.connectionpool:Starting new HTTPS connection (1): api.openweathermap.org:443
DEBUG:urllib3.connectionpool:https://api.openweathermap.org:443 "GET /data/2.5/weather?q=Krasnoyarsk&appid=da8eff3043fc441cca70712be72d110b&units=metric HTTP/1.1" 200 523
ERROR:django.request:Internal Server Error: /profile/
Traceback (most recent call last):
  File "C:\Users\Иван\AppData\Local\Programs\Python\Python38\lib\site-packages\django\template\base.py", line 880, in _resolve_lookup
    current = current[bit]
TypeError: 'ImageFieldFile' object is not subscriptable

During handling of the above exception, another exception occurred:

Traceback (most recent call last):
  File "C:\Users\Иван\AppData\Local\Programs\Python\Python38\lib\site-packages\django\core\handlers\exception.py", line 55, in inner
    response = get_response(request)
  File "C:\Users\Иван\AppData\Local\Programs\Python\Python38\lib\site-packages\django\core\handlers\base.py", line 197, in _get_response
    response = wrapped_callback(request, *callback_args, **callback_kwargs)
  File "C:\Users\Иван\AppData\Local\Programs\Python\Python38\lib\site-packages\django\contrib\auth\decorators.py", line 23, in _wrapped_view
    return view_func(request, *args, **kwargs)
  File "C:\Users\Иван\PycharmProjects\WeatherProject\Wardrobe-Weather-Project\WeatherProject\src\client\views.py", line 32, in profile
    return render(request, 'user/profile.html', context)
  File "C:\Users\Иван\AppData\Local\Programs\Python\Python38\lib\site-packages\django\shortcuts.py", line 24, in render
    content = loader.render_to_string(template_name, context, request, using=using)
  File "C:\Users\Иван\AppData\Local\Programs\Python\Python38\lib\site-packages\django\template\loader.py", line 62, in render_to_string
    return template.render(context, request)
  File "C:\Users\Иван\AppData\Local\Programs\Python\Python38\lib\site-packages\django\template\backends\django.py", line 62, in render
    return self.template.render(context)
  File "C:\Users\Иван\AppData\Local\Programs\Python\Python38\lib\site-packages\django\template\base.py", line 175, in render
    return self._render(context)
  File "C:\Users\Иван\AppData\Local\Programs\Python\Python38\lib\site-packages\django\test\utils.py", line 111, in instrumented_test_render
    return self.nodelist.render(context)
  File "C:\Users\Иван\AppData\Local\Programs\Python\Python38\lib\site-packages\django\template\base.py", line 1005, in render
    return SafeString("".join([node.render_annotated(context) for node in self]))
  File "C:\Users\Иван\AppData\Local\Programs\Python\Python38\lib\site-packages\django\template\base.py", line 1005, in <listcomp>
    return SafeString("".join([node.render_annotated(context) for node in self]))
  File "C:\Users\Иван\AppData\Local\Programs\Python\Python38\lib\site-packages\django\template\base.py", line 966, in render_annotated
    return self.render(context)
  File "C:\Users\Иван\AppData\Local\Programs\Python\Python38\lib\site-packages\django\template\defaulttags.py", line 238, in render
    nodelist.append(node.render_annotated(context))
  File "C:\Users\Иван\AppData\Local\Programs\Python\Python38\lib\site-packages\django\template\base.py", line 966, in render_annotated
    return self.render(context)
  File "C:\Users\Иван\AppData\Local\Programs\Python\Python38\lib\site-packages\django\template\defaulttags.py", line 238, in render
    nodelist.append(node.render_annotated(context))
  File "C:\Users\Иван\AppData\Local\Programs\Python\Python38\lib\site-packages\django\template\base.py", line 966, in render_annotated
    return self.render(context)
  File "C:\Users\Иван\AppData\Local\Programs\Python\Python38\lib\site-packages\django\template\base.py", line 1064, in render
    output = self.filter_expression.resolve(context)
  File "C:\Users\Иван\AppData\Local\Programs\Python\Python38\lib\site-packages\django\template\base.py", line 715, in resolve
    obj = self.var.resolve(context)
  File "C:\Users\Иван\AppData\Local\Programs\Python\Python38\lib\site-packages\django\template\base.py", line 847, in resolve
    value = self._resolve_lookup(context)
  File "C:\Users\Иван\AppData\Local\Programs\Python\Python38\lib\site-packages\django\template\base.py", line 890, in _resolve_lookup
    current = getattr(current, bit)
  File "C:\Users\Иван\AppData\Local\Programs\Python\Python38\lib\site-packages\django\db\models\fields\files.py", line 65, in url
    self._require_file()
  File "C:\Users\Иван\AppData\Local\Programs\Python\Python38\lib\site-packages\django\db\models\fields\files.py", line 40, in _require_file
    raise ValueError(
ValueError: The 'photo_of_clothes' attribute has no file associated with it.
DEBUG:urllib3.connectionpool:Starting new HTTPS connection (1): api.openweathermap.org:443
DEBUG:urllib3.connectionpool:https://api.openweathermap.org:443 "GET /data/2.5/weather?q=Krasnoyarsk&appid=da8eff3043fc441cca70712be72d110b&units=metric HTTP/1.1" 200 523
ERROR:django.request:Internal Server Error: /profile/
Traceback (most recent call last):
  File "C:\Users\Иван\AppData\Local\Programs\Python\Python38\lib\site-packages\django\template\base.py", line 880, in _resolve_lookup
    current = current[bit]
TypeError: 'ImageFieldFile' object is not subscriptable

During handling of the above exception, another exception occurred:

Traceback (most recent call last):
  File "C:\Users\Иван\AppData\Local\Programs\Python\Python38\lib\site-packages\django\core\handlers\exception.py", line 55, in inner
    response = get_response(request)
  File "C:\Users\Иван\AppData\Local\Programs\Python\Python38\lib\site-packages\django\core\handlers\base.py", line 197, in _get_response
    response = wrapped_callback(request, *callback_args, **callback_kwargs)
  File "C:\Users\Иван\AppData\Local\Programs\Python\Python38\lib\site-packages\django\contrib\auth\decorators.py", line 23, in _wrapped_view
    return view_func(request, *args, **kwargs)
  File "C:\Users\Иван\PycharmProjects\WeatherProject\Wardrobe-Weather-Project\WeatherProject\src\client\views.py", line 32, in profile
    return render(request, 'user/profile.html', context)
  File "C:\Users\Иван\AppData\Local\Programs\Python\Python38\lib\site-packages\django\shortcuts.py", line 24, in render
    content = loader.render_to_string(template_name, context, request, using=using)
  File "C:\Users\Иван\AppData\Local\Programs\Python\Python38\lib\site-packages\django\template\loader.py", line 62, in render_to_string
    return template.render(context, request)
  File "C:\Users\Иван\AppData\Local\Programs\Python\Python38\lib\site-packages\django\template\backends\django.py", line 62, in render
    return self.template.render(context)
  File "C:\Users\Иван\AppData\Local\Programs\Python\Python38\lib\site-packages\django\template\base.py", line 175, in render
    return self._render(context)
  File "C:\Users\Иван\AppData\Local\Programs\Python\Python38\lib\site-packages\django\test\utils.py", line 111, in instrumented_test_render
    return self.nodelist.render(context)
  File "C:\Users\Иван\AppData\Local\Programs\Python\Python38\lib\site-packages\django\template\base.py", line 1005, in render
    return SafeString("".join([node.render_annotated(context) for node in self]))
  File "C:\Users\Иван\AppData\Local\Programs\Python\Python38\lib\site-packages\django\template\base.py", line 1005, in <listcomp>
    return SafeString("".join([node.render_annotated(context) for node in self]))
  File "C:\Users\Иван\AppData\Local\Programs\Python\Python38\lib\site-packages\django\template\base.py", line 966, in render_annotated
    return self.render(context)
  File "C:\Users\Иван\AppData\Local\Programs\Python\Python38\lib\site-packages\django\template\defaulttags.py", line 238, in render
    nodelist.append(node.render_annotated(context))
  File "C:\Users\Иван\AppData\Local\Programs\Python\Python38\lib\site-packages\django\template\base.py", line 966, in render_annotated
    return self.render(context)
  File "C:\Users\Иван\AppData\Local\Programs\Python\Python38\lib\site-packages\django\template\defaulttags.py", line 238, in render
    nodelist.append(node.render_annotated(context))
  File "C:\Users\Иван\AppData\Local\Programs\Python\Python38\lib\site-packages\django\template\base.py", line 966, in render_annotated
    return self.render(context)
  File "C:\Users\Иван\AppData\Local\Programs\Python\Python38\lib\site-packages\django\template\base.py", line 1064, in render
    output = self.filter_expression.resolve(context)
  File "C:\Users\Иван\AppData\Local\Programs\Python\Python38\lib\site-packages\django\template\base.py", line 715, in resolve
    obj = self.var.resolve(context)
  File "C:\Users\Иван\AppData\Local\Programs\Python\Python38\lib\site-packages\django\template\base.py", line 847, in resolve
    value = self._resolve_lookup(context)
  File "C:\Users\Иван\AppData\Local\Programs\Python\Python38\lib\site-packages\django\template\base.py", line 890, in _resolve_lookup
    current = getattr(current, bit)
  File "C:\Users\Иван\AppData\Local\Programs\Python\Python38\lib\site-packages\django\db\models\fields\files.py", line 65, in url
    self._require_file()
  File "C:\Users\Иван\AppData\Local\Programs\Python\Python38\lib\site-packages\django\db\models\fields\files.py", line 40, in _require_file
    raise ValueError(
ValueError: The 'photo_of_clothes' attribute has no file associated with it.
DEBUG:urllib3.connectionpool:Starting new HTTPS connection (1): api.openweathermap.org:443
DEBUG:urllib3.connectionpool:https://api.openweathermap.org:443 "GET /data/2.5/weather?q=Krasnoyarsk&appid=da8eff3043fc441cca70712be72d110b&units=metric HTTP/1.1" 200 523
ERROR:django.request:Internal Server Error: /profile/
Traceback (most recent call last):
  File "C:\Users\Иван\AppData\Local\Programs\Python\Python38\lib\site-packages\django\template\base.py", line 880, in _resolve_lookup
    current = current[bit]
TypeError: 'ImageFieldFile' object is not subscriptable

During handling of the above exception, another exception occurred:

Traceback (most recent call last):
  File "C:\Users\Иван\AppData\Local\Programs\Python\Python38\lib\site-packages\django\core\handlers\exception.py", line 55, in inner
    response = get_response(request)
  File "C:\Users\Иван\AppData\Local\Programs\Python\Python38\lib\site-packages\django\core\handlers\base.py", line 197, in _get_response
    response = wrapped_callback(request, *callback_args, **callback_kwargs)
  File "C:\Users\Иван\AppData\Local\Programs\Python\Python38\lib\site-packages\django\contrib\auth\decorators.py", line 23, in _wrapped_view
    return view_func(request, *args, **kwargs)
  File "C:\Users\Иван\PycharmProjects\WeatherProject\Wardrobe-Weather-Project\WeatherProject\src\client\views.py", line 32, in profile
    return render(request, 'user/profile.html', context)
  File "C:\Users\Иван\AppData\Local\Programs\Python\Python38\lib\site-packages\django\shortcuts.py", line 24, in render
    content = loader.render_to_string(template_name, context, request, using=using)
  File "C:\Users\Иван\AppData\Local\Programs\Python\Python38\lib\site-packages\django\template\loader.py", line 62, in render_to_string
    return template.render(context, request)
  File "C:\Users\Иван\AppData\Local\Programs\Python\Python38\lib\site-packages\django\template\backends\django.py", line 62, in render
    return self.template.render(context)
  File "C:\Users\Иван\AppData\Local\Programs\Python\Python38\lib\site-packages\django\template\base.py", line 175, in render
    return self._render(context)
  File "C:\Users\Иван\AppData\Local\Programs\Python\Python38\lib\site-packages\django\test\utils.py", line 111, in instrumented_test_render
    return self.nodelist.render(context)
  File "C:\Users\Иван\AppData\Local\Programs\Python\Python38\lib\site-packages\django\template\base.py", line 1005, in render
    return SafeString("".join([node.render_annotated(context) for node in self]))
  File "C:\Users\Иван\AppData\Local\Programs\Python\Python38\lib\site-packages\django\template\base.py", line 1005, in <listcomp>
    return SafeString("".join([node.render_annotated(context) for node in self]))
  File "C:\Users\Иван\AppData\Local\Programs\Python\Python38\lib\site-packages\django\template\base.py", line 966, in render_annotated
    return self.render(context)
  File "C:\Users\Иван\AppData\Local\Programs\Python\Python38\lib\site-packages\django\template\defaulttags.py", line 238, in render
    nodelist.append(node.render_annotated(context))
  File "C:\Users\Иван\AppData\Local\Programs\Python\Python38\lib\site-packages\django\template\base.py", line 966, in render_annotated
    return self.render(context)
  File "C:\Users\Иван\AppData\Local\Programs\Python\Python38\lib\site-packages\django\template\defaulttags.py", line 238, in render
    nodelist.append(node.render_annotated(context))
  File "C:\Users\Иван\AppData\Local\Programs\Python\Python38\lib\site-packages\django\template\base.py", line 966, in render_annotated
    return self.render(context)
  File "C:\Users\Иван\AppData\Local\Programs\Python\Python38\lib\site-packages\django\template\base.py", line 1064, in render
    output = self.filter_expression.resolve(context)
  File "C:\Users\Иван\AppData\Local\Programs\Python\Python38\lib\site-packages\django\template\base.py", line 715, in resolve
    obj = self.var.resolve(context)
  File "C:\Users\Иван\AppData\Local\Programs\Python\Python38\lib\site-packages\django\template\base.py", line 847, in resolve
    value = self._resolve_lookup(context)
  File "C:\Users\Иван\AppData\Local\Programs\Python\Python38\lib\site-packages\django\template\base.py", line 890, in _resolve_lookup
    current = getattr(current, bit)
  File "C:\Users\Иван\AppData\Local\Programs\Python\Python38\lib\site-packages\django\db\models\fields\files.py", line 65, in url
    self._require_file()
  File "C:\Users\Иван\AppData\Local\Programs\Python\Python38\lib\site-packages\django\db\models\fields\files.py", line 40, in _require_file
    raise ValueError(
ValueError: The 'photo_of_clothes' attribute has no file associated with it.
DEBUG:urllib3.connectionpool:Starting new HTTPS connection (1): api.openweathermap.org:443
DEBUG:urllib3.connectionpool:https://api.openweathermap.org:443 "GET /data/2.5/weather?q=Krasnoyarsk&appid=da8eff3043fc441cca70712be72d110b&units=metric HTTP/1.1" 200 523
DEBUG:urllib3.connectionpool:Starting new HTTPS connection (1): api.openweathermap.org:443
DEBUG:urllib3.connectionpool:https://api.openweathermap.org:443 "GET /data/2.5/weather?q=Krasnoyarsk&appid=da8eff3043fc441cca70712be72d110b&units=metric HTTP/1.1" 200 523
WARNING:django.request:Not Found: /
WARNING:django.request:Not Found: /favicon.ico
DEBUG:urllib3.connectionpool:Starting new HTTPS connection (1): api.openweathermap.org:443
DEBUG:urllib3.connectionpool:https://api.openweathermap.org:443 "GET /data/2.5/weather?q=Krasnoyarsk&appid=da8eff3043fc441cca70712be72d110b&units=metric HTTP/1.1" 200 524
DEBUG:urllib3.connectionpool:Starting new HTTPS connection (1): api.openweathermap.org:443
DEBUG:urllib3.connectionpool:https://api.openweathermap.org:443 "GET /data/2.5/weather?q=Krasnoyarsk&appid=da8eff3043fc441cca70712be72d110b&units=metric HTTP/1.1" 200 524
DEBUG:urllib3.connectionpool:Starting new HTTPS connection (1): api.openweathermap.org:443
DEBUG:urllib3.connectionpool:https://api.openweathermap.org:443 "GET /data/2.5/weather?q=Sochi&appid=da8eff3043fc441cca70712be72d110b&units=metric HTTP/1.1" 200 527
DEBUG:urllib3.connectionpool:Starting new HTTPS connection (1): api.openweathermap.org:443
DEBUG:urllib3.connectionpool:https://api.openweathermap.org:443 "GET /data/2.5/weather?q=Sochi&appid=da8eff3043fc441cca70712be72d110b&units=metric HTTP/1.1" 200 527
DEBUG:urllib3.connectionpool:Starting new HTTPS connection (1): api.openweathermap.org:443
DEBUG:urllib3.connectionpool:https://api.openweathermap.org:443 "GET /data/2.5/weather?q=Sochi&appid=da8eff3043fc441cca70712be72d110b&units=metric HTTP/1.1" 200 527
DEBUG:PIL.Image:Importing BlpImagePlugin
DEBUG:PIL.Image:Importing BmpImagePlugin
DEBUG:PIL.Image:Importing BufrStubImagePlugin
DEBUG:PIL.Image:Importing CurImagePlugin
DEBUG:PIL.Image:Importing DcxImagePlugin
DEBUG:PIL.Image:Importing DdsImagePlugin
DEBUG:PIL.Image:Importing EpsImagePlugin
DEBUG:PIL.Image:Importing FitsImagePlugin
DEBUG:PIL.Image:Importing FliImagePlugin
DEBUG:PIL.Image:Importing FpxImagePlugin
DEBUG:PIL.Image:Image: failed to import FpxImagePlugin: No module named 'olefile'
DEBUG:PIL.Image:Importing FtexImagePlugin
DEBUG:PIL.Image:Importing GbrImagePlugin
DEBUG:PIL.Image:Importing GifImagePlugin
DEBUG:PIL.Image:Importing GribStubImagePlugin
DEBUG:PIL.Image:Importing Hdf5StubImagePlugin
DEBUG:PIL.Image:Importing IcnsImagePlugin
DEBUG:PIL.Image:Importing IcoImagePlugin
DEBUG:PIL.Image:Importing ImImagePlugin
DEBUG:PIL.Image:Importing ImtImagePlugin
DEBUG:PIL.Image:Importing IptcImagePlugin
DEBUG:PIL.Image:Importing JpegImagePlugin
DEBUG:PIL.Image:Importing Jpeg2KImagePlugin
DEBUG:PIL.Image:Importing McIdasImagePlugin
DEBUG:PIL.Image:Importing MicImagePlugin
DEBUG:PIL.Image:Image: failed to import MicImagePlugin: No module named 'olefile'
DEBUG:PIL.Image:Importing MpegImagePlugin
DEBUG:PIL.Image:Importing MpoImagePlugin
DEBUG:PIL.Image:Importing MspImagePlugin
DEBUG:PIL.Image:Importing PalmImagePlugin
DEBUG:PIL.Image:Importing PcdImagePlugin
DEBUG:PIL.Image:Importing PcxImagePlugin
DEBUG:PIL.Image:Importing PdfImagePlugin
DEBUG:PIL.Image:Importing PixarImagePlugin
DEBUG:PIL.Image:Importing PngImagePlugin
DEBUG:PIL.Image:Importing PpmImagePlugin
DEBUG:PIL.Image:Importing PsdImagePlugin
DEBUG:PIL.Image:Importing QoiImagePlugin
DEBUG:PIL.Image:Importing SgiImagePlugin
DEBUG:PIL.Image:Importing SpiderImagePlugin
DEBUG:PIL.Image:Importing SunImagePlugin
DEBUG:PIL.Image:Importing TgaImagePlugin
DEBUG:PIL.Image:Importing TiffImagePlugin
DEBUG:PIL.Image:Importing WebPImagePlugin
DEBUG:PIL.Image:Importing WmfImagePlugin
DEBUG:PIL.Image:Importing XbmImagePlugin
DEBUG:PIL.Image:Importing XpmImagePlugin
DEBUG:PIL.Image:Importing XVThumbImagePlugin
DEBUG:urllib3.connectionpool:Starting new HTTPS connection (1): api.openweathermap.org:443
DEBUG:urllib3.connectionpool:https://api.openweathermap.org:443 "GET /data/2.5/weather?q=Sochi&appid=da8eff3043fc441cca70712be72d110b&units=metric HTTP/1.1" 200 527
WARNING:django.request:Not Found: /we
WARNING:django.request:Not Found: /weathe
DEBUG:urllib3.connectionpool:Starting new HTTPS connection (1): api.openweathermap.org:443
DEBUG:urllib3.connectionpool:https://api.openweathermap.org:443 "GET /data/2.5/weather?q=Sochi&appid=da8eff3043fc441cca70712be72d110b&units=metric HTTP/1.1" 200 527
DEBUG:urllib3.connectionpool:Starting new HTTPS connection (1): api.openweathermap.org:443
DEBUG:urllib3.connectionpool:https://api.openweathermap.org:443 "GET /data/2.5/weather?q=Sochi&appid=da8eff3043fc441cca70712be72d110b&units=metric HTTP/1.1" 200 527
DEBUG:urllib3.connectionpool:Starting new HTTPS connection (1): api.openweathermap.org:443
DEBUG:urllib3.connectionpool:https://api.openweathermap.org:443 "GET /data/2.5/weather?q=Sochi&appid=da8eff3043fc441cca70712be72d110b&units=metric HTTP/1.1" 200 527
ERROR:django.request:Internal Server Error: /admin/wardrobe/clothes/add/
Traceback (most recent call last):
  File "C:\Users\Иван\AppData\Local\Programs\Python\Python38\lib\site-packages\django\core\handlers\exception.py", line 55, in inner
    response = get_response(request)
  File "C:\Users\Иван\AppData\Local\Programs\Python\Python38\lib\site-packages\django\core\handlers\base.py", line 197, in _get_response
    response = wrapped_callback(request, *callback_args, **callback_kwargs)
  File "C:\Users\Иван\AppData\Local\Programs\Python\Python38\lib\site-packages\django\contrib\admin\options.py", line 686, in wrapper
    return self.admin_site.admin_view(view)(*args, **kwargs)
  File "C:\Users\Иван\AppData\Local\Programs\Python\Python38\lib\site-packages\django\utils\decorators.py", line 133, in _wrapped_view
    response = view_func(request, *args, **kwargs)
  File "C:\Users\Иван\AppData\Local\Programs\Python\Python38\lib\site-packages\django\views\decorators\cache.py", line 62, in _wrapped_view_func
    response = view_func(request, *args, **kwargs)
  File "C:\Users\Иван\AppData\Local\Programs\Python\Python38\lib\site-packages\django\contrib\admin\sites.py", line 242, in inner
    return view(request, *args, **kwargs)
  File "C:\Users\Иван\AppData\Local\Programs\Python\Python38\lib\site-packages\django\contrib\admin\options.py", line 1890, in add_view
    return self.changeform_view(request, None, form_url, extra_context)
  File "C:\Users\Иван\AppData\Local\Programs\Python\Python38\lib\site-packages\django\utils\decorators.py", line 46, in _wrapper
    return bound_method(*args, **kwargs)
  File "C:\Users\Иван\AppData\Local\Programs\Python\Python38\lib\site-packages\django\utils\decorators.py", line 133, in _wrapped_view
    response = view_func(request, *args, **kwargs)
  File "C:\Users\Иван\AppData\Local\Programs\Python\Python38\lib\site-packages\django\contrib\admin\options.py", line 1750, in changeform_view
    return self._changeform_view(request, object_id, form_url, extra_context)
  File "C:\Users\Иван\AppData\Local\Programs\Python\Python38\lib\site-packages\django\contrib\admin\options.py", line 1796, in _changeform_view
    form_validated = form.is_valid()
  File "C:\Users\Иван\AppData\Local\Programs\Python\Python38\lib\site-packages\django\forms\forms.py", line 205, in is_valid
    return self.is_bound and not self.errors
  File "C:\Users\Иван\AppData\Local\Programs\Python\Python38\lib\site-packages\django\forms\forms.py", line 200, in errors
    self.full_clean()
  File "C:\Users\Иван\AppData\Local\Programs\Python\Python38\lib\site-packages\django\forms\forms.py", line 439, in full_clean
    self._post_clean()
  File "C:\Users\Иван\AppData\Local\Programs\Python\Python38\lib\site-packages\django\forms\models.py", line 492, in _post_clean
    self.instance.full_clean(exclude=exclude, validate_unique=False)
  File "C:\Users\Иван\AppData\Local\Programs\Python\Python38\lib\site-packages\django\db\models\base.py", line 1452, in full_clean
    self.clean()
  File "C:\Users\Иван\PycharmProjects\WeatherProject\Wardrobe-Weather-Project\WeatherProject\src\wardrobe\models.py", line 51, in clean
    if not isinstance(self.optimal_temperature.get("min_temp"), (int, float)):
AttributeError: 'NoneType' object has no attribute 'get'
ERROR:django.request:Internal Server Error: /admin/wardrobe/clothes/add/
Traceback (most recent call last):
  File "C:\Users\Иван\AppData\Local\Programs\Python\Python38\lib\site-packages\django\core\handlers\exception.py", line 55, in inner
    response = get_response(request)
  File "C:\Users\Иван\AppData\Local\Programs\Python\Python38\lib\site-packages\django\core\handlers\base.py", line 197, in _get_response
    response = wrapped_callback(request, *callback_args, **callback_kwargs)
  File "C:\Users\Иван\AppData\Local\Programs\Python\Python38\lib\site-packages\django\contrib\admin\options.py", line 686, in wrapper
    return self.admin_site.admin_view(view)(*args, **kwargs)
  File "C:\Users\Иван\AppData\Local\Programs\Python\Python38\lib\site-packages\django\utils\decorators.py", line 133, in _wrapped_view
    response = view_func(request, *args, **kwargs)
  File "C:\Users\Иван\AppData\Local\Programs\Python\Python38\lib\site-packages\django\views\decorators\cache.py", line 62, in _wrapped_view_func
    response = view_func(request, *args, **kwargs)
  File "C:\Users\Иван\AppData\Local\Programs\Python\Python38\lib\site-packages\django\contrib\admin\sites.py", line 242, in inner
    return view(request, *args, **kwargs)
  File "C:\Users\Иван\AppData\Local\Programs\Python\Python38\lib\site-packages\django\contrib\admin\options.py", line 1890, in add_view
    return self.changeform_view(request, None, form_url, extra_context)
  File "C:\Users\Иван\AppData\Local\Programs\Python\Python38\lib\site-packages\django\utils\decorators.py", line 46, in _wrapper
    return bound_method(*args, **kwargs)
  File "C:\Users\Иван\AppData\Local\Programs\Python\Python38\lib\site-packages\django\utils\decorators.py", line 133, in _wrapped_view
    response = view_func(request, *args, **kwargs)
  File "C:\Users\Иван\AppData\Local\Programs\Python\Python38\lib\site-packages\django\contrib\admin\options.py", line 1750, in changeform_view
    return self._changeform_view(request, object_id, form_url, extra_context)
  File "C:\Users\Иван\AppData\Local\Programs\Python\Python38\lib\site-packages\django\contrib\admin\options.py", line 1796, in _changeform_view
    form_validated = form.is_valid()
  File "C:\Users\Иван\AppData\Local\Programs\Python\Python38\lib\site-packages\django\forms\forms.py", line 205, in is_valid
    return self.is_bound and not self.errors
  File "C:\Users\Иван\AppData\Local\Programs\Python\Python38\lib\site-packages\django\forms\forms.py", line 200, in errors
    self.full_clean()
  File "C:\Users\Иван\AppData\Local\Programs\Python\Python38\lib\site-packages\django\forms\forms.py", line 439, in full_clean
    self._post_clean()
  File "C:\Users\Иван\AppData\Local\Programs\Python\Python38\lib\site-packages\django\forms\models.py", line 492, in _post_clean
    self.instance.full_clean(exclude=exclude, validate_unique=False)
  File "C:\Users\Иван\AppData\Local\Programs\Python\Python38\lib\site-packages\django\db\models\base.py", line 1452, in full_clean
    self.clean()
  File "C:\Users\Иван\PycharmProjects\WeatherProject\Wardrobe-Weather-Project\WeatherProject\src\wardrobe\models.py", line 51, in clean
    if not isinstance(self.optimal_temperature.get("min_temp"), (int, float)):
AttributeError: 'NoneType' object has no attribute 'get'
DEBUG:urllib3.connectionpool:Starting new HTTPS connection (1): api.openweathermap.org:443
DEBUG:urllib3.connectionpool:https://api.openweathermap.org:443 "GET /data/2.5/weather?q=Sochi&appid=da8eff3043fc441cca70712be72d110b&units=metric HTTP/1.1" 200 527
DEBUG:urllib3.connectionpool:Starting new HTTPS connection (1): api.openweathermap.org:443
DEBUG:urllib3.connectionpool:https://api.openweathermap.org:443 "GET /data/2.5/weather?q=Sochi&appid=da8eff3043fc441cca70712be72d110b&units=metric HTTP/1.1" 200 527
DEBUG:urllib3.connectionpool:Starting new HTTPS connection (1): api.openweathermap.org:443
DEBUG:urllib3.connectionpool:https://api.openweathermap.org:443 "GET /data/2.5/weather?q=Sochi&appid=da8eff3043fc441cca70712be72d110b&units=metric HTTP/1.1" 200 527
WARNING:django.request:Not Found: /
WARNING:django.request:Not Found: /favicon.ico
DEBUG:urllib3.connectionpool:Starting new HTTPS connection (1): api.openweathermap.org:443
DEBUG:urllib3.connectionpool:https://api.openweathermap.org:443 "GET /data/2.5/weather?q=Sochi&appid=da8eff3043fc441cca70712be72d110b&units=metric HTTP/1.1" 200 513
DEBUG:urllib3.connectionpool:Starting new HTTPS connection (1): api.openweathermap.org:443
DEBUG:urllib3.connectionpool:https://api.openweathermap.org:443 "GET /data/2.5/weather?q=Sochi&appid=da8eff3043fc441cca70712be72d110b&units=metric HTTP/1.1" 200 513
INFO:django.utils.autoreload:C:\Users\Иван\PycharmProjects\WeatherProject\Wardrobe-Weather-Project\WeatherProject\src\wardrobe\services\outfit_generation_logic.py changed, reloading.
DEBUG:urllib3.connectionpool:Starting new HTTPS connection (1): api.openweathermap.org:443
DEBUG:urllib3.connectionpool:https://api.openweathermap.org:443 "GET /data/2.5/weather?q=Sochi&appid=da8eff3043fc441cca70712be72d110b&units=metric HTTP/1.1" 200 514
ERROR:django.request:Internal Server Error: /weather/
Traceback (most recent call last):
  File "C:\Users\Иван\AppData\Local\Programs\Python\Python38\lib\site-packages\django\core\handlers\exception.py", line 55, in inner
    response = get_response(request)
  File "C:\Users\Иван\AppData\Local\Programs\Python\Python38\lib\site-packages\django\core\handlers\base.py", line 197, in _get_response
    response = wrapped_callback(request, *callback_args, **callback_kwargs)
  File "C:\Users\Иван\PycharmProjects\WeatherProject\Wardrobe-Weather-Project\WeatherProject\src\weather\views.py", line 20, in fetch_weather
    clothes_list_2 = outfit_logic(user, temperature, style_id)
  File "C:\Users\Иван\PycharmProjects\WeatherProject\Wardrobe-Weather-Project\WeatherProject\src\wardrobe\services\outfit_generation_logic.py", line 121, in outfit_logic
    for key, value in clothes.lists.items():
AttributeError: 'QuerySet' object has no attribute 'lists'
DEBUG:urllib3.connectionpool:Starting new HTTPS connection (1): api.openweathermap.org:443
DEBUG:urllib3.connectionpool:https://api.openweathermap.org:443 "GET /data/2.5/weather?q=Sochi&appid=da8eff3043fc441cca70712be72d110b&units=metric HTTP/1.1" 200 514
ERROR:django.request:Internal Server Error: /weather/
Traceback (most recent call last):
  File "C:\Users\Иван\AppData\Local\Programs\Python\Python38\lib\site-packages\django\core\handlers\exception.py", line 55, in inner
    response = get_response(request)
  File "C:\Users\Иван\AppData\Local\Programs\Python\Python38\lib\site-packages\django\core\handlers\base.py", line 197, in _get_response
    response = wrapped_callback(request, *callback_args, **callback_kwargs)
  File "C:\Users\Иван\PycharmProjects\WeatherProject\Wardrobe-Weather-Project\WeatherProject\src\weather\views.py", line 20, in fetch_weather
    clothes_list_2 = outfit_logic(user, temperature, style_id)
  File "C:\Users\Иван\PycharmProjects\WeatherProject\Wardrobe-Weather-Project\WeatherProject\src\wardrobe\services\outfit_generation_logic.py", line 121, in outfit_logic
    for key, value in clothes.lists.items():
AttributeError: 'QuerySet' object has no attribute 'lists'
WARNING:django.request:Not Found: /
DEBUG:urllib3.connectionpool:Starting new HTTPS connection (1): api.openweathermap.org:443
DEBUG:urllib3.connectionpool:https://api.openweathermap.org:443 "GET /data/2.5/weather?q=Sochi&appid=da8eff3043fc441cca70712be72d110b&units=metric HTTP/1.1" 200 514
ERROR:django.request:Internal Server Error: /weather/
Traceback (most recent call last):
  File "C:\Users\Иван\AppData\Local\Programs\Python\Python38\lib\site-packages\django\core\handlers\exception.py", line 55, in inner
    response = get_response(request)
  File "C:\Users\Иван\AppData\Local\Programs\Python\Python38\lib\site-packages\django\core\handlers\base.py", line 197, in _get_response
    response = wrapped_callback(request, *callback_args, **callback_kwargs)
  File "C:\Users\Иван\PycharmProjects\WeatherProject\Wardrobe-Weather-Project\WeatherProject\src\weather\views.py", line 20, in fetch_weather
    clothes_list_2 = outfit_logic(user, temperature, style_id)
  File "C:\Users\Иван\PycharmProjects\WeatherProject\Wardrobe-Weather-Project\WeatherProject\src\wardrobe\services\outfit_generation_logic.py", line 121, in outfit_logic
    for key, value in clothes.lists.items():
AttributeError: 'QuerySet' object has no attribute 'lists'
INFO:django.utils.autoreload:C:\Users\Иван\PycharmProjects\WeatherProject\Wardrobe-Weather-Project\WeatherProject\src\wardrobe\services\outfit_generation_logic.py changed, reloading.
DEBUG:urllib3.connectionpool:Starting new HTTPS connection (1): api.openweathermap.org:443
DEBUG:urllib3.connectionpool:https://api.openweathermap.org:443 "GET /data/2.5/weather?q=Sochi&appid=da8eff3043fc441cca70712be72d110b&units=metric HTTP/1.1" 200 514
DEBUG:urllib3.connectionpool:Starting new HTTPS connection (1): api.openweathermap.org:443
DEBUG:urllib3.connectionpool:https://api.openweathermap.org:443 "GET /data/2.5/weather?q=Sochi&appid=da8eff3043fc441cca70712be72d110b&units=metric HTTP/1.1" 200 514
DEBUG:urllib3.connectionpool:Starting new HTTPS connection (1): api.openweathermap.org:443
DEBUG:urllib3.connectionpool:https://api.openweathermap.org:443 "GET /data/2.5/weather?q=Sochi&appid=da8eff3043fc441cca70712be72d110b&units=metric HTTP/1.1" 200 514
INFO:django.utils.autoreload:C:\Users\Иван\PycharmProjects\WeatherProject\Wardrobe-Weather-Project\WeatherProject\src\wardrobe\services\outfit_generation_logic.py changed, reloading.
INFO:django.utils.autoreload:C:\Users\Иван\PycharmProjects\WeatherProject\Wardrobe-Weather-Project\WeatherProject\src\wardrobe\services\outfit_generation_logic.py changed, reloading.
INFO:django.utils.autoreload:C:\Users\Иван\PycharmProjects\WeatherProject\Wardrobe-Weather-Project\WeatherProject\src\wardrobe\services\outfit_generation_logic.py changed, reloading.
DEBUG:urllib3.connectionpool:Starting new HTTPS connection (1): api.openweathermap.org:443
DEBUG:urllib3.connectionpool:https://api.openweathermap.org:443 "GET /data/2.5/weather?q=Sochi&appid=da8eff3043fc441cca70712be72d110b&units=metric HTTP/1.1" 200 514
INFO:django.utils.autoreload:C:\Users\Иван\PycharmProjects\WeatherProject\Wardrobe-Weather-Project\WeatherProject\src\wardrobe\services\outfit_generation_logic.py changed, reloading.
DEBUG:urllib3.connectionpool:Starting new HTTPS connection (1): api.openweathermap.org:443
DEBUG:urllib3.connectionpool:https://api.openweathermap.org:443 "GET /data/2.5/weather?q=Sochi&appid=da8eff3043fc441cca70712be72d110b&units=metric HTTP/1.1" 200 514
INFO:django.utils.autoreload:C:\Users\Иван\PycharmProjects\WeatherProject\Wardrobe-Weather-Project\WeatherProject\src\wardrobe\services\outfit_generation_logic.py changed, reloading.
DEBUG:urllib3.connectionpool:Starting new HTTPS connection (1): api.openweathermap.org:443
DEBUG:urllib3.connectionpool:https://api.openweathermap.org:443 "GET /data/2.5/weather?q=Sochi&appid=da8eff3043fc441cca70712be72d110b&units=metric HTTP/1.1" 200 514
INFO:django.utils.autoreload:C:\Users\Иван\PycharmProjects\WeatherProject\Wardrobe-Weather-Project\WeatherProject\src\wardrobe\services\outfit_generation_logic.py changed, reloading.
INFO:django.utils.autoreload:C:\Users\Иван\PycharmProjects\WeatherProject\Wardrobe-Weather-Project\WeatherProject\src\wardrobe\services\outfit_generation_logic.py changed, reloading.
INFO:django.utils.autoreload:C:\Users\Иван\PycharmProjects\WeatherProject\Wardrobe-Weather-Project\WeatherProject\src\weather\views.py changed, reloading.
INFO:django.utils.autoreload:C:\Users\Иван\PycharmProjects\WeatherProject\Wardrobe-Weather-Project\WeatherProject\src\weather\views.py changed, reloading.
INFO:django.utils.autoreload:C:\Users\Иван\PycharmProjects\WeatherProject\Wardrobe-Weather-Project\WeatherProject\src\weather\views.py changed, reloading.
INFO:django.utils.autoreload:C:\Users\Иван\PycharmProjects\WeatherProject\Wardrobe-Weather-Project\WeatherProject\src\weather\views.py changed, reloading.
DEBUG:urllib3.connectionpool:Starting new HTTPS connection (1): api.openweathermap.org:443
DEBUG:urllib3.connectionpool:https://api.openweathermap.org:443 "GET /data/2.5/weather?q=Sochi&appid=da8eff3043fc441cca70712be72d110b&units=metric HTTP/1.1" 200 515
ERROR:django.request:Internal Server Error: /weather/
Traceback (most recent call last):
  File "C:\Users\Иван\AppData\Local\Programs\Python\Python38\lib\site-packages\django\core\handlers\exception.py", line 55, in inner
    response = get_response(request)
  File "C:\Users\Иван\AppData\Local\Programs\Python\Python38\lib\site-packages\django\core\handlers\base.py", line 197, in _get_response
    response = wrapped_callback(request, *callback_args, **callback_kwargs)
  File "C:\Users\Иван\PycharmProjects\WeatherProject\Wardrobe-Weather-Project\WeatherProject\src\weather\views.py", line 21, in fetch_weather
    clothes_list_test = OutfitLogic.outfit_logic(user, temperature, style_id)
  File "C:\Users\Иван\PycharmProjects\WeatherProject\Wardrobe-Weather-Project\WeatherProject\src\wardrobe\services\test_file.py", line 107, in outfit_logic
    ClothesManager.fill_clothes_list(filtered_clothes_by_style, temperature, clothes_list)
  File "C:\Users\Иван\PycharmProjects\WeatherProject\Wardrobe-Weather-Project\WeatherProject\src\wardrobe\services\test_file.py", line 61, in fill_clothes_list
    if ClothesManager.is_suitable_temperature(item, temperature) and ClothesManager.is_suitable_season(
TypeError: is_suitable_season() missing 1 required positional argument: 'today_season'
INFO:django.utils.autoreload:C:\Users\Иван\PycharmProjects\WeatherProject\Wardrobe-Weather-Project\WeatherProject\src\wardrobe\services\test_file.py changed, reloading.
DEBUG:urllib3.connectionpool:Starting new HTTPS connection (1): api.openweathermap.org:443
DEBUG:urllib3.connectionpool:https://api.openweathermap.org:443 "GET /data/2.5/weather?q=Sochi&appid=da8eff3043fc441cca70712be72d110b&units=metric HTTP/1.1" 200 515
DEBUG:urllib3.connectionpool:Starting new HTTPS connection (1): api.openweathermap.org:443
DEBUG:urllib3.connectionpool:https://api.openweathermap.org:443 "GET /data/2.5/weather?q=Sochi&appid=da8eff3043fc441cca70712be72d110b&units=metric HTTP/1.1" 200 515
INFO:django.utils.autoreload:C:\Users\Иван\PycharmProjects\WeatherProject\Wardrobe-Weather-Project\WeatherProject\src\wardrobe\services\test_file.py changed, reloading.
INFO:django.utils.autoreload:C:\Users\Иван\PycharmProjects\WeatherProject\Wardrobe-Weather-Project\WeatherProject\src\wardrobe\services\test_file.py changed, reloading.
WARNING:django.request:Not Found: /
DEBUG:urllib3.connectionpool:Starting new HTTPS connection (1): api.openweathermap.org:443
DEBUG:urllib3.connectionpool:https://api.openweathermap.org:443 "GET /data/2.5/weather?q=Sochi&appid=da8eff3043fc441cca70712be72d110b&units=metric HTTP/1.1" 200 515
DEBUG:urllib3.connectionpool:Starting new HTTPS connection (1): api.openweathermap.org:443
DEBUG:urllib3.connectionpool:https://api.openweathermap.org:443 "GET /data/2.5/weather?q=Sochi&appid=da8eff3043fc441cca70712be72d110b&units=metric HTTP/1.1" 200 515
DEBUG:urllib3.connectionpool:Starting new HTTPS connection (1): api.openweathermap.org:443
DEBUG:urllib3.connectionpool:https://api.openweathermap.org:443 "GET /data/2.5/weather?q=Sochi&appid=da8eff3043fc441cca70712be72d110b&units=metric HTTP/1.1" 200 515
INFO:django.utils.autoreload:C:\Users\Иван\PycharmProjects\WeatherProject\Wardrobe-Weather-Project\WeatherProject\src\wardrobe\services\test_file.py changed, reloading.
DEBUG:urllib3.connectionpool:Starting new HTTPS connection (1): api.openweathermap.org:443
DEBUG:urllib3.connectionpool:https://api.openweathermap.org:443 "GET /data/2.5/weather?q=Sochi&appid=da8eff3043fc441cca70712be72d110b&units=metric HTTP/1.1" 200 515
DEBUG:urllib3.connectionpool:Starting new HTTPS connection (1): api.openweathermap.org:443
DEBUG:urllib3.connectionpool:https://api.openweathermap.org:443 "GET /data/2.5/weather?q=Sochi&appid=da8eff3043fc441cca70712be72d110b&units=metric HTTP/1.1" 200 515
INFO:django.utils.autoreload:C:\Users\Иван\PycharmProjects\WeatherProject\Wardrobe-Weather-Project\WeatherProject\src\wardrobe\services\test_file.py changed, reloading.
DEBUG:urllib3.connectionpool:Starting new HTTPS connection (1): api.openweathermap.org:443
DEBUG:urllib3.connectionpool:https://api.openweathermap.org:443 "GET /data/2.5/weather?q=Sochi&appid=da8eff3043fc441cca70712be72d110b&units=metric HTTP/1.1" 200 515
ERROR:django.request:Internal Server Error: /weather/
Traceback (most recent call last):
  File "C:\Users\Иван\AppData\Local\Programs\Python\Python38\lib\site-packages\django\core\handlers\exception.py", line 55, in inner
    response = get_response(request)
  File "C:\Users\Иван\AppData\Local\Programs\Python\Python38\lib\site-packages\django\core\handlers\base.py", line 197, in _get_response
    response = wrapped_callback(request, *callback_args, **callback_kwargs)
  File "C:\Users\Иван\PycharmProjects\WeatherProject\Wardrobe-Weather-Project\WeatherProject\src\weather\views.py", line 21, in fetch_weather
    clothes_list_test = OutfitLogic.outfit_logic(user, temperature, style_id)
  File "C:\Users\Иван\PycharmProjects\WeatherProject\Wardrobe-Weather-Project\WeatherProject\src\wardrobe\services\test_file.py", line 107, in outfit_logic
    ClothesManager.fill_clothes_list(filtered_clothes_by_style, temperature, today_season, clothes_list)
  File "C:\Users\Иван\PycharmProjects\WeatherProject\Wardrobe-Weather-Project\WeatherProject\src\wardrobe\services\test_file.py", line 61, in fill_clothes_list
    if ClothesManager.is_suitable_temperature(item, temperature) and ClothesManager.is_suitable_season(
TypeError: is_suitable_temperature() takes 1 positional argument but 2 were given
INFO:django.utils.autoreload:C:\Users\Иван\PycharmProjects\WeatherProject\Wardrobe-Weather-Project\WeatherProject\src\wardrobe\services\test_file.py changed, reloading.
INFO:django.utils.autoreload:C:\Users\Иван\PycharmProjects\WeatherProject\Wardrobe-Weather-Project\WeatherProject\src\wardrobe\services\test_file.py changed, reloading.
INFO:django.utils.autoreload:C:\Users\Иван\PycharmProjects\WeatherProject\Wardrobe-Weather-Project\WeatherProject\src\wardrobe\services\test_file.py changed, reloading.
INFO:django.utils.autoreload:C:\Users\Иван\PycharmProjects\WeatherProject\Wardrobe-Weather-Project\WeatherProject\src\wardrobe\services\test_file.py changed, reloading.
INFO:django.utils.autoreload:C:\Users\Иван\PycharmProjects\WeatherProject\Wardrobe-Weather-Project\WeatherProject\src\wardrobe\services\test_file.py changed, reloading.
INFO:django.utils.autoreload:C:\Users\Иван\PycharmProjects\WeatherProject\Wardrobe-Weather-Project\WeatherProject\src\wardrobe\services\test_file.py changed, reloading.
INFO:django.utils.autoreload:C:\Users\Иван\PycharmProjects\WeatherProject\Wardrobe-Weather-Project\WeatherProject\src\wardrobe\services\test_file.py changed, reloading.
INFO:django.utils.autoreload:C:\Users\Иван\PycharmProjects\WeatherProject\Wardrobe-Weather-Project\WeatherProject\src\wardrobe\services\test_file.py changed, reloading.
INFO:django.utils.autoreload:C:\Users\Иван\PycharmProjects\WeatherProject\Wardrobe-Weather-Project\WeatherProject\src\wardrobe\services\test_file.py changed, reloading.
INFO:django.utils.autoreload:C:\Users\Иван\PycharmProjects\WeatherProject\Wardrobe-Weather-Project\WeatherProject\src\wardrobe\services\test_file.py changed, reloading.
INFO:django.utils.autoreload:C:\Users\Иван\PycharmProjects\WeatherProject\Wardrobe-Weather-Project\WeatherProject\src\wardrobe\services\test_file.py changed, reloading.
INFO:django.utils.autoreload:C:\Users\Иван\PycharmProjects\WeatherProject\Wardrobe-Weather-Project\WeatherProject\src\wardrobe\services\test_file.py changed, reloading.
INFO:django.utils.autoreload:C:\Users\Иван\PycharmProjects\WeatherProject\Wardrobe-Weather-Project\WeatherProject\src\wardrobe\services\test_file.py changed, reloading.
INFO:django.utils.autoreload:C:\Users\Иван\PycharmProjects\WeatherProject\Wardrobe-Weather-Project\WeatherProject\src\wardrobe\services\test_file.py changed, reloading.
INFO:django.utils.autoreload:C:\Users\Иван\PycharmProjects\WeatherProject\Wardrobe-Weather-Project\WeatherProject\src\wardrobe\services\test_file.py changed, reloading.
INFO:django.utils.autoreload:C:\Users\Иван\PycharmProjects\WeatherProject\Wardrobe-Weather-Project\WeatherProject\src\wardrobe\services\test_file.py changed, reloading.
INFO:django.utils.autoreload:C:\Users\Иван\PycharmProjects\WeatherProject\Wardrobe-Weather-Project\WeatherProject\src\wardrobe\services\test_file.py changed, reloading.
INFO:django.utils.autoreload:C:\Users\Иван\PycharmProjects\WeatherProject\Wardrobe-Weather-Project\WeatherProject\src\wardrobe\services\test_file.py changed, reloading.
INFO:django.utils.autoreload:C:\Users\Иван\PycharmProjects\WeatherProject\Wardrobe-Weather-Project\WeatherProject\src\wardrobe\services\test_file.py changed, reloading.
INFO:django.utils.autoreload:C:\Users\Иван\PycharmProjects\WeatherProject\Wardrobe-Weather-Project\WeatherProject\src\wardrobe\services\test_file.py changed, reloading.
INFO:django.utils.autoreload:C:\Users\Иван\PycharmProjects\WeatherProject\Wardrobe-Weather-Project\WeatherProject\src\wardrobe\services\test_file.py changed, reloading.
INFO:django.utils.autoreload:C:\Users\Иван\PycharmProjects\WeatherProject\Wardrobe-Weather-Project\WeatherProject\src\wardrobe\services\test_file.py changed, reloading.
INFO:django.utils.autoreload:C:\Users\Иван\PycharmProjects\WeatherProject\Wardrobe-Weather-Project\WeatherProject\src\wardrobe\services\test_file.py changed, reloading.
INFO:django.utils.autoreload:C:\Users\Иван\PycharmProjects\WeatherProject\Wardrobe-Weather-Project\WeatherProject\src\wardrobe\services\test_file.py changed, reloading.
INFO:django.utils.autoreload:C:\Users\Иван\PycharmProjects\WeatherProject\Wardrobe-Weather-Project\WeatherProject\src\wardrobe\services\test_file.py changed, reloading.
INFO:django.utils.autoreload:C:\Users\Иван\PycharmProjects\WeatherProject\Wardrobe-Weather-Project\WeatherProject\src\wardrobe\services\test_file.py changed, reloading.
INFO:django.utils.autoreload:C:\Users\Иван\PycharmProjects\WeatherProject\Wardrobe-Weather-Project\WeatherProject\src\wardrobe\services\test_file.py changed, reloading.
INFO:django.utils.autoreload:C:\Users\Иван\PycharmProjects\WeatherProject\Wardrobe-Weather-Project\WeatherProject\src\wardrobe\services\test_file.py changed, reloading.
DEBUG:urllib3.connectionpool:Starting new HTTPS connection (1): api.openweathermap.org:443
DEBUG:urllib3.connectionpool:https://api.openweathermap.org:443 "GET /data/2.5/weather?q=Sochi&appid=da8eff3043fc441cca70712be72d110b&units=metric HTTP/1.1" 200 515
ERROR:django.request:Internal Server Error: /weather/
Traceback (most recent call last):
  File "C:\Users\Иван\AppData\Local\Programs\Python\Python38\lib\site-packages\django\core\handlers\exception.py", line 55, in inner
    response = get_response(request)
  File "C:\Users\Иван\AppData\Local\Programs\Python\Python38\lib\site-packages\django\core\handlers\base.py", line 197, in _get_response
    response = wrapped_callback(request, *callback_args, **callback_kwargs)
  File "C:\Users\Иван\PycharmProjects\WeatherProject\Wardrobe-Weather-Project\WeatherProject\src\weather\views.py", line 21, in fetch_weather
    clothes_list_test = OutfitLogic.outfit_logic(user, temperature, style_id)
TypeError: outfit_logic() missing 1 required positional argument: 'style'
INFO:django.utils.autoreload:C:\Users\Иван\PycharmProjects\WeatherProject\Wardrobe-Weather-Project\WeatherProject\src\wardrobe\services\test_file.py changed, reloading.
INFO:django.utils.autoreload:C:\Users\Иван\PycharmProjects\WeatherProject\Wardrobe-Weather-Project\WeatherProject\src\wardrobe\services\test_file.py changed, reloading.
INFO:django.utils.autoreload:C:\Users\Иван\PycharmProjects\WeatherProject\Wardrobe-Weather-Project\WeatherProject\src\wardrobe\services\test_file.py changed, reloading.
DEBUG:urllib3.connectionpool:Starting new HTTPS connection (1): api.openweathermap.org:443
DEBUG:urllib3.connectionpool:https://api.openweathermap.org:443 "GET /data/2.5/weather?q=Sochi&appid=da8eff3043fc441cca70712be72d110b&units=metric HTTP/1.1" 200 513
DEBUG:urllib3.connectionpool:Starting new HTTPS connection (1): api.openweathermap.org:443
DEBUG:urllib3.connectionpool:https://api.openweathermap.org:443 "GET /data/2.5/weather?q=Sochi&appid=da8eff3043fc441cca70712be72d110b&units=metric HTTP/1.1" 200 513
INFO:django.utils.autoreload:C:\Users\Иван\PycharmProjects\WeatherProject\Wardrobe-Weather-Project\WeatherProject\src\wardrobe\services\test_file.py changed, reloading.
INFO:django.utils.autoreload:C:\Users\Иван\PycharmProjects\WeatherProject\Wardrobe-Weather-Project\WeatherProject\src\wardrobe\services\test_file.py changed, reloading.
INFO:django.utils.autoreload:C:\Users\Иван\PycharmProjects\WeatherProject\Wardrobe-Weather-Project\WeatherProject\src\wardrobe\services\test_file.py changed, reloading.
INFO:django.utils.autoreload:C:\Users\Иван\PycharmProjects\WeatherProject\Wardrobe-Weather-Project\WeatherProject\src\wardrobe\services\test_file.py changed, reloading.
INFO:django.utils.autoreload:C:\Users\Иван\PycharmProjects\WeatherProject\Wardrobe-Weather-Project\WeatherProject\src\wardrobe\services\test_file.py changed, reloading.
INFO:django.utils.autoreload:C:\Users\Иван\PycharmProjects\WeatherProject\Wardrobe-Weather-Project\WeatherProject\src\wardrobe\services\test_file.py changed, reloading.
DEBUG:urllib3.connectionpool:Starting new HTTPS connection (1): api.openweathermap.org:443
DEBUG:urllib3.connectionpool:https://api.openweathermap.org:443 "GET /data/2.5/weather?q=Sochi&appid=da8eff3043fc441cca70712be72d110b&units=metric HTTP/1.1" 200 513
DEBUG:urllib3.connectionpool:Starting new HTTPS connection (1): api.openweathermap.org:443
DEBUG:urllib3.connectionpool:https://api.openweathermap.org:443 "GET /data/2.5/weather?q=Sochi&appid=da8eff3043fc441cca70712be72d110b&units=metric HTTP/1.1" 200 513
DEBUG:urllib3.connectionpool:Starting new HTTPS connection (1): api.openweathermap.org:443
DEBUG:urllib3.connectionpool:https://api.openweathermap.org:443 "GET /data/2.5/weather?q=Sochi&appid=da8eff3043fc441cca70712be72d110b&units=metric HTTP/1.1" 200 513
INFO:django.utils.autoreload:C:\Users\Иван\PycharmProjects\WeatherProject\Wardrobe-Weather-Project\WeatherProject\src\wardrobe\services\test_file.py changed, reloading.
DEBUG:urllib3.connectionpool:Starting new HTTPS connection (1): api.openweathermap.org:443
DEBUG:urllib3.connectionpool:https://api.openweathermap.org:443 "GET /data/2.5/weather?q=Sochi&appid=da8eff3043fc441cca70712be72d110b&units=metric HTTP/1.1" 200 513
INFO:django.utils.autoreload:C:\Users\Иван\PycharmProjects\WeatherProject\Wardrobe-Weather-Project\WeatherProject\src\wardrobe\services\test_file.py changed, reloading.
DEBUG:urllib3.connectionpool:Starting new HTTPS connection (1): api.openweathermap.org:443
DEBUG:urllib3.connectionpool:https://api.openweathermap.org:443 "GET /data/2.5/weather?q=Sochi&appid=da8eff3043fc441cca70712be72d110b&units=metric HTTP/1.1" 200 513
INFO:django.utils.autoreload:C:\Users\Иван\PycharmProjects\WeatherProject\Wardrobe-Weather-Project\WeatherProject\src\weather\views.py changed, reloading.
DEBUG:urllib3.connectionpool:Starting new HTTPS connection (1): api.openweathermap.org:443
DEBUG:urllib3.connectionpool:https://api.openweathermap.org:443 "GET /data/2.5/weather?q=Sochi&appid=da8eff3043fc441cca70712be72d110b&units=metric HTTP/1.1" 200 513
DEBUG:urllib3.connectionpool:Starting new HTTPS connection (1): api.openweathermap.org:443
DEBUG:urllib3.connectionpool:https://api.openweathermap.org:443 "GET /data/2.5/weather?q=Sochi&appid=da8eff3043fc441cca70712be72d110b&units=metric HTTP/1.1" 200 513
DEBUG:urllib3.connectionpool:Starting new HTTPS connection (1): api.openweathermap.org:443
DEBUG:urllib3.connectionpool:https://api.openweathermap.org:443 "GET /data/2.5/weather?q=Sochi&appid=da8eff3043fc441cca70712be72d110b&units=metric HTTP/1.1" 200 513
INFO:django.utils.autoreload:C:\Users\Иван\PycharmProjects\WeatherProject\Wardrobe-Weather-Project\WeatherProject\src\weather\views.py changed, reloading.
DEBUG:urllib3.connectionpool:Starting new HTTPS connection (1): api.openweathermap.org:443
DEBUG:urllib3.connectionpool:https://api.openweathermap.org:443 "GET /data/2.5/weather?q=Sochi&appid=da8eff3043fc441cca70712be72d110b&units=metric HTTP/1.1" 200 513
DEBUG:urllib3.connectionpool:Starting new HTTPS connection (1): api.openweathermap.org:443
DEBUG:urllib3.connectionpool:https://api.openweathermap.org:443 "GET /data/2.5/weather?q=Sochi&appid=da8eff3043fc441cca70712be72d110b&units=metric HTTP/1.1" 200 513
DEBUG:urllib3.connectionpool:Starting new HTTPS connection (1): api.openweathermap.org:443
DEBUG:urllib3.connectionpool:https://api.openweathermap.org:443 "GET /data/2.5/weather?q=Sochi&appid=da8eff3043fc441cca70712be72d110b&units=metric HTTP/1.1" 200 513
